Workbook

Sheet README
A1: Kenya Industry Opportunity Radar: model
A2: Real data: KNBS Quarterly GDP Q1 2026, CBK Bank Supervision Annual Report 2025, CBK Credit Officer Survey (June 2026), KNBS Economic Survey 2026.
A4: How to read: Scorecard ranks ten industry groups on five pillars. Change the scenario or weights on Inputs; everything recalculates.
A5: Blue cells are inputs; black cells are formulas. GDP and Credit_Map hold the editable mapping of activities and bank sectors to industry groups.
A6: Pillars: Scale (2025 real value added), Recent growth (Q1 2026 vs Q1 2025), Track record (2021-25 CAGR), Credit demand (net % of credit officers seeing higher demand, June 2026, loan-weighted), Credit health (inverse of NPL ratio, Dec 2025).
A7: Each pillar is min-max scaled to 0-100 across the ten groups. Groups with no matching bank sector (Public Sector & Development, Health) get a neutral 50 on the two credit pillars.
A8: Transport and Communication is one CBK bank sector; it is shared by Technology, Media & Telecom and Transport & Logistics.
A9: Industry groups are an analyst grouping for this exercise, not any firm's official taxonomy. Professional services, other services, FISIM and taxes on products are excluded.
A10: Checks sheet compares every headline number with the independent Python calculation (analysis/model.py).

Sheet Scorecard
A1: Industry Opportunity Radar: scorecard
A2: Real KNBS and CBK data. Scenario selected on Inputs. Ranks 1 = highest priority.
A3: Scenario: | B3: =Inputs!B3 -> Balanced
A5: Industry group | B5: Value added 2025 (KSh m) | C5: Share of GDP % | D5: Growth 2025 % | E5: CAGR 2021-25 % | F5: Growth Q1 2026 % | G5: Gross loans (KSh m) | H5: NPL ratio % | I5: Credit demand net % | J5: Scale (0-100) | K5: Recent growth | L5: Track record | M5: Credit demand | N5: Credit health | O5: Score | P5: Rank | Q5: Tier | R5: Evidence
A6: Financial Services | B6: =SUMIFS(GDP!$E$5:$E$21,GDP!$B$5:$B$21,$A6) -> 1134626 | C6: =B6/GDP!$E$22*100 -> 10.836496 | D6: =B6/SUMIFS(GDP!$D$5:$D$21,GDP!$B$5:$B$21,$A6)*100-100 -> 6.5213493 | E6: =((B6/SUMIFS(GDP!$C$5:$C$21,GDP!$B$5:$B$21,$A6))^(1/4)-1)*100 -> 9.0282808 | F6: =SUMIFS(GDP!$G$5:$G$21,GDP!$B$5:$B$21,$A6)/SUMIFS(GDP!$F$5:$F$21,GDP!$B$5:$B$21,$A6)*100-100 -> 6.2783503 | G6: =IF(SUMIFS(Credit_Map!$C$5:$C$15,Credit_Map!$A$5:$A$15,$A6)=0,"",SUMIFS(Credit_Map!$C$5:$C$15,Credit_Map!$A$5:$A$15,$A6)) -> 241698.4 | H6: =IF(G6="","",SUMIFS(Credit_Map!$D$5:$D$15,Credit_Map!$A$5:$A$15,$A6)/G6*100) -> 3.2537245 | I6: =IF(G6="","",SUMPRODUCT((Credit_Map!$A$5:$A$15=$A6)*Credit_Map!$C$5:$C$15*(Credit_Map!$E$5:$E$15-Credit_Map!$F$5:$F$15))/G6) -> 22 | J6: =IF(B6="","",((B6-MIN($B$6:$B$15))/(MAX($B$6:$B$15)-MIN($B$6:$B$15))*100)) -> 52.73637 | K6: =IF(F6="","",((F6-MIN($F$6:$F$15))/(MAX($F$6:$F$15)-MIN($F$6:$F$15))*100)) -> 100 | L6: =IF(E6="","",((E6-MIN($E$6:$E$15))/(MAX($E$6:$E$15)-MIN($E$6:$E$15))*100)) -> 100 | M6: =IF(I6="","",((I6-MIN($I$6:$I$15))/(MAX($I$6:$I$15)-MIN($I$6:$I$15))*100)) -> 30.998016 | N6: =IF(H6="","",100-((H6-MIN($H$6:$H$15))/(MAX($H$6:$H$15)-MIN($H$6:$H$15))*100)) -> 100 | O6: =(IF(ISNUMBER(J6),J6,Inputs!$B$4)*INDEX(Inputs!$B$9:$F$13,MATCH(Inputs!$B$3,Inputs!$A$9:$A$13,0),1)+IF(ISNUMBER(K6),K6,Inputs!$B$4)*INDEX(Inputs!$B$9:$F$13,MATCH(Inputs!$B$3,Inputs!$A$9:$A$13,0),2)+IF(ISNUMBER(L6),L6,Inputs!$B$4)*INDEX(Inputs!$B$9:$F$13,MATCH(Inputs!$B$3,Inputs!$A$9:$A$13,0),3)+IF(ISNUMBER(M6),M6,Inputs!$B$4)*INDEX(Inputs!$B$9:$F$13,MATCH(Inputs!$B$3,Inputs!$A$9:$A$13,0),4)+IF(ISNUMBER(N6),N6,Inputs!$B$4)*INDEX(Inputs!$B$9:$F$13,MATCH(Inputs!$B$3,Inputs!$A$9:$A$13,0),5))/INDEX(Inputs!$G$9:$G$13,MATCH(Inputs!$B$3,Inputs!$A$9:$A$13,0)) -> 76.746877 | P6: =RANK(O6,$O$6:$O$15) -> 1 | Q6: =IF(P6<=Inputs!$B$5,"Lead",IF(P6<=Inputs!$B$6,"Grow","Selective")) -> Lead | R6: =IF(G6="","Growth only (credit neutral)","Growth + credit") -> Growth + credit
A7: Energy & Resources | B7: =SUMIFS(GDP!$E$5:$E$21,GDP!$B$5:$B$21,$A7) -> 385040 | C7: =B7/GDP!$E$22*100 -> 3.6774095 | D7: =B7/SUMIFS(GDP!$D$5:$D$21,GDP!$B$5:$B$21,$A7)*100-100 -> 7.8694495 | E7: =((B7/SUMIFS(GDP!$C$5:$C$21,GDP!$B$5:$B$21,$A7))^(1/4)-1)*100 -> 3.4953054 | F7: =SUMIFS(GDP!$G$5:$G$21,GDP!$B$5:$B$21,$A7)/SUMIFS(GDP!$F$5:$F$21,GDP!$B$5:$B$21,$A7)*100-100 -> 5.6731222 | G7: =IF(SUMIFS(Credit_Map!$C$5:$C$15,Credit_Map!$A$5:$A$15,$A7)=0,"",SUMIFS(Credit_Map!$C$5:$C$15,Credit_Map!$A$5:$A$15,$A7)) -> 180935.1 | H7: =IF(G7="","",SUMIFS(Credit_Map!$D$5:$D$15,Credit_Map!$A$5:$A$15,$A7)/G7*100) -> 9.555581 | I7: =IF(G7="","",SUMPRODUCT((Credit_Map!$A$5:$A$15=$A7)*Credit_Map!$C$5:$C$15*(Credit_Map!$E$5:$E$15-Credit_Map!$F$5:$F$15))/G7) -> 25.99623 | J7: =IF(B7="","",((B7-MIN($B$6:$B$15))/(MAX($B$6:$B$15)-MIN($B$6:$B$15))*100)) -> 7.6458596 | K7: =IF(F7="","",((F7-MIN($F$6:$F$15))/(MAX($F$6:$F$15)-MIN($F$6:$F$15))*100)) -> 77.417487 | L7: =IF(E7="","",((E7-MIN($E$6:$E$15))/(MAX($E$6:$E$15)-MIN($E$6:$E$15))*100)) -> 16.288237 | M7: =IF(I7="","",((I7-MIN($I$6:$I$15))/(MAX($I$6:$I$15)-MIN($I$6:$I$15))*100)) -> 39.846245 | N7: =IF(H7="","",100-((H7-MIN($H$6:$H$15))/(MAX($H$6:$H$15)-MIN($H$6:$H$15))*100)) -> 69.788031 | O7: =(IF(ISNUMBER(J7),J7,Inputs!$B$4)*INDEX(Inputs!$B$9:$F$13,MATCH(Inputs!$B$3,Inputs!$A$9:$A$13,0),1)+IF(ISNUMBER(K7),K7,Inputs!$B$4)*INDEX(Inputs!$B$9:$F$13,MATCH(Inputs!$B$3,Inputs!$A$9:$A$13,0),2)+IF(ISNUMBER(L7),L7,Inputs!$B$4)*INDEX(Inputs!$B$9:$F$13,MATCH(Inputs!$B$3,Inputs!$A$9:$A$13,0),3)+IF(ISNUMBER(M7),M7,Inputs!$B$4)*INDEX(Inputs!$B$9:$F$13,MATCH(Inputs!$B$3,Inputs!$A$9:$A$13,0),4)+IF(ISNUMBER(N7),N7,Inputs!$B$4)*INDEX(Inputs!$B$9:$F$13,MATCH(Inputs!$B$3,Inputs!$A$9:$A$13,0),5))/INDEX(Inputs!$G$9:$G$13,MATCH(Inputs!$B$3,Inputs!$A$9:$A$13,0)) -> 45.253634 | P7: =RANK(O7,$O$6:$O$15) -> 4 | Q7: =IF(P7<=Inputs!$B$5,"Lead",IF(P7<=Inputs!$B$6,"Grow","Selective")) -> Grow | R7: =IF(G7="","Growth only (credit neutral)","Growth + credit") -> Growth + credit
A8: Technology, Media & Telecom | B8: =SUMIFS(GDP!$E$5:$E$21,GDP!$B$5:$B$21,$A8) -> 391886 | C8: =B8/GDP!$E$22*100 -> 3.7427937 | D8: =B8/SUMIFS(GDP!$D$5:$D$21,GDP!$B$5:$B$21,$A8)*100-100 -> 4.821591 | E8: =((B8/SUMIFS(GDP!$C$5:$C$21,GDP!$B$5:$B$21,$A8))^(1/4)-1)*100 -> 7.7969831 | F8: =SUMIFS(GDP!$G$5:$G$21,GDP!$B$5:$B$21,$A8)/SUMIFS(GDP!$F$5:$F$21,GDP!$B$5:$B$21,$A8)*100-100 -> 4.9743935 | G8: =IF(SUMIFS(Credit_Map!$C$5:$C$15,Credit_Map!$A$5:$A$15,$A8)=0,"",SUMIFS(Credit_Map!$C$5:$C$15,Credit_Map!$A$5:$A$15,$A8)) -> 321105.5 | H8: =IF(G8="","",SUMIFS(Credit_Map!$D$5:$D$15,Credit_Map!$A$5:$A$15,$A8)/G8*100) -> 16.561815 | I8: =IF(G8="","",SUMPRODUCT((Credit_Map!$A$5:$A$15=$A8)*Credit_Map!$C$5:$C$15*(Credit_Map!$E$5:$E$15-Credit_Map!$F$5:$F$15))/G8) -> 8 | J8: =IF(B8="","",((B8-MIN($B$6:$B$15))/(MAX($B$6:$B$15)-MIN($B$6:$B$15))*100)) -> 8.0576731 | K8: =IF(F8="","",((F8-MIN($F$6:$F$15))/(MAX($F$6:$F$15)-MIN($F$6:$F$15))*100)) -> 51.346241 | L8: =IF(E8="","",((E8-MIN($E$6:$E$15))/(MAX($E$6:$E$15)-MIN($E$6:$E$15))*100)) -> 81.370944 | M8: =IF(I8="","",((I8-MIN($I$6:$I$15))/(MAX($I$6:$I$15)-MIN($I$6:$I$15))*100)) -> 0 | N8: =IF(H8="","",100-((H8-MIN($H$6:$H$15))/(MAX($H$6:$H$15)-MIN($H$6:$H$15))*100)) -> 36.199176 | O8: =(IF(ISNUMBER(J8),J8,Inputs!$B$4)*INDEX(Inputs!$B$9:$F$13,MATCH(Inputs!$B$3,Inputs!$A$9:$A$13,0),1)+IF(ISNUMBER(K8),K8,Inputs!$B$4)*INDEX(Inputs!$B$9:$F$13,MATCH(Inputs!$B$3,Inputs!$A$9:$A$13,0),2)+IF(ISNUMBER(L8),L8,Inputs!$B$4)*INDEX(Inputs!$B$9:$F$13,MATCH(Inputs!$B$3,Inputs!$A$9:$A$13,0),3)+IF(ISNUMBER(M8),M8,Inputs!$B$4)*INDEX(Inputs!$B$9:$F$13,MATCH(Inputs!$B$3,Inputs!$A$9:$A$13,0),4)+IF(ISNUMBER(N8),N8,Inputs!$B$4)*INDEX(Inputs!$B$9:$F$13,MATCH(Inputs!$B$3,Inputs!$A$9:$A$13,0),5))/INDEX(Inputs!$G$9:$G$13,MATCH(Inputs!$B$3,Inputs!$A$9:$A$13,0)) -> 33.893572 | P8: =RANK(O8,$O$6:$O$15) -> 7 | Q8: =IF(P8<=Inputs!$B$5,"Lead",IF(P8<=Inputs!$B$6,"Grow","Selective")) -> Grow | R8: =IF(G8="","Growth only (credit neutral)","Growth + credit") -> Growth + credit
A9: Transport & Logistics | B9: =SUMIFS(GDP!$E$5:$E$21,GDP!$B$5:$B$21,$A9) -> 1077187 | C9: =B9/GDP!$E$22*100 -> 10.287912 | D9: =B9/SUMIFS(GDP!$D$5:$D$21,GDP!$B$5:$B$21,$A9)*100-100 -> 3.6957208 | E9: =((B9/SUMIFS(GDP!$C$5:$C$21,GDP!$B$5:$B$21,$A9))^(1/4)-1)*100 -> 4.8295283 | F9: =SUMIFS(GDP!$G$5:$G$21,GDP!$B$5:$B$21,$A9)/SUMIFS(GDP!$F$5:$F$21,GDP!$B$5:$B$21,$A9)*100-100 -> 3.5982762 | G9: =IF(SUMIFS(Credit_Map!$C$5:$C$15,Credit_Map!$A$5:$A$15,$A9)=0,"",SUMIFS(Credit_Map!$C$5:$C$15,Credit_Map!$A$5:$A$15,$A9)) -> 321105.5 | H9: =IF(G9="","",SUMIFS(Credit_Map!$D$5:$D$15,Credit_Map!$A$5:$A$15,$A9)/G9*100) -> 16.561815 | I9: =IF(G9="","",SUMPRODUCT((Credit_Map!$A$5:$A$15=$A9)*Credit_Map!$C$5:$C$15*(Credit_Map!$E$5:$E$15-Credit_Map!$F$5:$F$15))/G9) -> 8 | J9: =IF(B9="","",((B9-MIN($B$6:$B$15))/(MAX($B$6:$B$15)-MIN($B$6:$B$15))*100)) -> 49.281191 | K9: =IF(F9="","",((F9-MIN($F$6:$F$15))/(MAX($F$6:$F$15)-MIN($F$6:$F$15))*100)) -> 0 | L9: =IF(E9="","",((E9-MIN($E$6:$E$15))/(MAX($E$6:$E$15)-MIN($E$6:$E$15))*100)) -> 36.474509 | M9: =IF(I9="","",((I9-MIN($I$6:$I$15))/(MAX($I$6:$I$15)-MIN($I$6:$I$15))*100)) -> 0 | N9: =IF(H9="","",100-((H9-MIN($H$6:$H$15))/(MAX($H$6:$H$15)-MIN($H$6:$H$15))*100)) -> 36.199176 | O9: =(IF(ISNUMBER(J9),J9,Inputs!$B$4)*INDEX(Inputs!$B$9:$F$13,MATCH(Inputs!$B$3,Inputs!$A$9:$A$13,0),1)+IF(ISNUMBER(K9),K9,Inputs!$B$4)*INDEX(Inputs!$B$9:$F$13,MATCH(Inputs!$B$3,Inputs!$A$9:$A$13,0),2)+IF(ISNUMBER(L9),L9,Inputs!$B$4)*INDEX(Inputs!$B$9:$F$13,MATCH(Inputs!$B$3,Inputs!$A$9:$A$13,0),3)+IF(ISNUMBER(M9),M9,Inputs!$B$4)*INDEX(Inputs!$B$9:$F$13,MATCH(Inputs!$B$3,Inputs!$A$9:$A$13,0),4)+IF(ISNUMBER(N9),N9,Inputs!$B$4)*INDEX(Inputs!$B$9:$F$13,MATCH(Inputs!$B$3,Inputs!$A$9:$A$13,0),5))/INDEX(Inputs!$G$9:$G$13,MATCH(Inputs!$B$3,Inputs!$A$9:$A$13,0)) -> 22.56725 | P9: =RANK(O9,$O$6:$O$15) -> 10 | Q9: =IF(P9<=Inputs!$B$5,"Lead",IF(P9<=Inputs!$B$6,"Grow","Selective")) -> Selective | R9: =IF(G9="","Growth only (credit neutral)","Growth + credit") -> Growth + credit
A10: Public Sector & Development | B10: =SUMIFS(GDP!$E$5:$E$21,GDP!$B$5:$B$21,$A10) -> 1273606 | C10: =B10/GDP!$E$22*100 -> 12.163855 | D10: =B10/SUMIFS(GDP!$D$5:$D$21,GDP!$B$5:$B$21,$A10)*100-100 -> 5.9295658 | E10: =((B10/SUMIFS(GDP!$C$5:$C$21,GDP!$B$5:$B$21,$A10))^(1/4)-1)*100 -> 5.5228987 | F10: =SUMIFS(GDP!$G$5:$G$21,GDP!$B$5:$B$21,$A10)/SUMIFS(GDP!$F$5:$F$21,GDP!$B$5:$B$21,$A10)*100-100 -> 5.9081245 | G10: =IF(SUMIFS(Credit_Map!$C$5:$C$15,Credit_Map!$A$5:$A$15,$A10)=0,"",SUMIFS(Credit_Map!$C$5:$C$15,Credit_Map!$A$5:$A$15,$A10)) | H10: =IF(G10="","",SUMIFS(Credit_Map!$D$5:$D$15,Credit_Map!$A$5:$A$15,$A10)/G10*100) | I10: =IF(G10="","",SUMPRODUCT((Credit_Map!$A$5:$A$15=$A10)*Credit_Map!$C$5:$C$15*(Credit_Map!$E$5:$E$15-Credit_Map!$F$5:$F$15))/G10) | J10: =IF(B10="","",((B10-MIN($B$6:$B$15))/(MAX($B$6:$B$15)-MIN($B$6:$B$15))*100)) -> 61.096557 | K10: =IF(F10="","",((F10-MIN($F$6:$F$15))/(MAX($F$6:$F$15)-MIN($F$6:$F$15))*100)) -> 86.185987 | L10: =IF(E10="","",((E10-MIN($E$6:$E$15))/(MAX($E$6:$E$15)-MIN($E$6:$E$15))*100)) -> 46.964933 | M10: =IF(I10="","",((I10-MIN($I$6:$I$15))/(MAX($I$6:$I$15)-MIN($I$6:$I$15))*100)) | N10: =IF(H10="","",100-((H10-MIN($H$6:$H$15))/(MAX($H$6:$H$15)-MIN($H$6:$H$15))*100)) | O10: =(IF(ISNUMBER(J10),J10,Inputs!$B$4)*INDEX(Inputs!$B$9:$F$13,MATCH(Inputs!$B$3,Inputs!$A$9:$A$13,0),1)+IF(ISNUMBER(K10),K10,Inputs!$B$4)*INDEX(Inputs!$B$9:$F$13,MATCH(Inputs!$B$3,Inputs!$A$9:$A$13,0),2)+IF(ISNUMBER(L10),L10,Inputs!$B$4)*INDEX(Inputs!$B$9:$F$13,MATCH(Inputs!$B$3,Inputs!$A$9:$A$13,0),3)+IF(ISNUMBER(M10),M10,Inputs!$B$4)*INDEX(Inputs!$B$9:$F$13,MATCH(Inputs!$B$3,Inputs!$A$9:$A$13,0),4)+IF(ISNUMBER(N10),N10,Inputs!$B$4)*INDEX(Inputs!$B$9:$F$13,MATCH(Inputs!$B$3,Inputs!$A$9:$A$13,0),5))/INDEX(Inputs!$G$9:$G$13,MATCH(Inputs!$B$3,Inputs!$A$9:$A$13,0)) -> 60.810548 | P10: =RANK(O10,$O$6:$O$15) -> 3 | Q10: =IF(P10<=Inputs!$B$5,"Lead",IF(P10<=Inputs!$B$6,"Grow","Selective")) -> Lead | R10: =IF(G10="","Growth only (credit neutral)","Growth + credit") -> Growth only (credit neutral)
A11: Health | B11: =SUMIFS(GDP!$E$5:$E$21,GDP!$B$5:$B$21,$A11) -> 257935 | C11: =B11/GDP!$E$22*100 -> 2.4634652 | D11: =B11/SUMIFS(GDP!$D$5:$D$21,GDP!$B$5:$B$21,$A11)*100-100 -> 5.5250992 | E11: =((B11/SUMIFS(GDP!$C$5:$C$21,GDP!$B$5:$B$21,$A11))^(1/4)-1)*100 -> 4.8367026 | F11: =SUMIFS(GDP!$G$5:$G$21,GDP!$B$5:$B$21,$A11)/SUMIFS(GDP!$F$5:$F$21,GDP!$B$5:$B$21,$A11)*100-100 -> 4.3111255 | G11: =IF(SUMIFS(Credit_Map!$C$5:$C$15,Credit_Map!$A$5:$A$15,$A11)=0,"",SUMIFS(Credit_Map!$C$5:$C$15,Credit_Map!$A$5:$A$15,$A11)) | H11: =IF(G11="","",SUMIFS(Credit_Map!$D$5:$D$15,Credit_Map!$A$5:$A$15,$A11)/G11*100) | I11: =IF(G11="","",SUMPRODUCT((Credit_Map!$A$5:$A$15=$A11)*Credit_Map!$C$5:$C$15*(Credit_Map!$E$5:$E$15-Credit_Map!$F$5:$F$15))/G11) | J11: =IF(B11="","",((B11-MIN($B$6:$B$15))/(MAX($B$6:$B$15)-MIN($B$6:$B$15))*100)) -> 0 | K11: =IF(F11="","",((F11-MIN($F$6:$F$15))/(MAX($F$6:$F$15)-MIN($F$6:$F$15))*100)) -> 26.598122 | L11: =IF(E11="","",((E11-MIN($E$6:$E$15))/(MAX($E$6:$E$15)-MIN($E$6:$E$15))*100)) -> 36.583054 | M11: =IF(I11="","",((I11-MIN($I$6:$I$15))/(MAX($I$6:$I$15)-MIN($I$6:$I$15))*100)) | N11: =IF(H11="","",100-((H11-MIN($H$6:$H$15))/(MAX($H$6:$H$15)-MIN($H$6:$H$15))*100)) | O11: =(IF(ISNUMBER(J11),J11,Inputs!$B$4)*INDEX(Inputs!$B$9:$F$13,MATCH(Inputs!$B$3,Inputs!$A$9:$A$13,0),1)+IF(ISNUMBER(K11),K11,Inputs!$B$4)*INDEX(Inputs!$B$9:$F$13,MATCH(Inputs!$B$3,Inputs!$A$9:$A$13,0),2)+IF(ISNUMBER(L11),L11,Inputs!$B$4)*INDEX(Inputs!$B$9:$F$13,MATCH(Inputs!$B$3,Inputs!$A$9:$A$13,0),3)+IF(ISNUMBER(M11),M11,Inputs!$B$4)*INDEX(Inputs!$B$9:$F$13,MATCH(Inputs!$B$3,Inputs!$A$9:$A$13,0),4)+IF(ISNUMBER(N11),N11,Inputs!$B$4)*INDEX(Inputs!$B$9:$F$13,MATCH(Inputs!$B$3,Inputs!$A$9:$A$13,0),5))/INDEX(Inputs!$G$9:$G$13,MATCH(Inputs!$B$3,Inputs!$A$9:$A$13,0)) -> 32.136989 | P11: =RANK(O11,$O$6:$O$15) -> 8 | Q11: =IF(P11<=Inputs!$B$5,"Lead",IF(P11<=Inputs!$B$6,"Grow","Selective")) -> Selective | R11: =IF(G11="","Growth only (credit neutral)","Growth + credit") -> Growth only (credit neutral)
A12: Consumer & Retail | B12: =SUMIFS(GDP!$E$5:$E$21,GDP!$B$5:$B$21,$A12) -> 1105605 | C12: =B12/GDP!$E$22*100 -> 10.559325 | D12: =B12/SUMIFS(GDP!$D$5:$D$21,GDP!$B$5:$B$21,$A12)*100-100 -> 5.5367401 | E12: =((B12/SUMIFS(GDP!$C$5:$C$21,GDP!$B$5:$B$21,$A12))^(1/4)-1)*100 -> 6.2588958 | F12: =SUMIFS(GDP!$G$5:$G$21,GDP!$B$5:$B$21,$A12)/SUMIFS(GDP!$F$5:$F$21,GDP!$B$5:$B$21,$A12)*100-100 -> 5.8041588 | G12: =IF(SUMIFS(Credit_Map!$C$5:$C$15,Credit_Map!$A$5:$A$15,$A12)=0,"",SUMIFS(Credit_Map!$C$5:$C$15,Credit_Map!$A$5:$A$15,$A12)) -> 956946.1 | H12: =IF(G12="","",SUMIFS(Credit_Map!$D$5:$D$15,Credit_Map!$A$5:$A$15,$A12)/G12*100) -> 20.191461 | I12: =IF(G12="","",SUMPRODUCT((Credit_Map!$A$5:$A$15=$A12)*Credit_Map!$C$5:$C$15*(Credit_Map!$E$5:$E$15-Credit_Map!$F$5:$F$15))/G12) -> 53.164181 | J12: =IF(B12="","",((B12-MIN($B$6:$B$15))/(MAX($B$6:$B$15)-MIN($B$6:$B$15))*100)) -> 50.990644 | K12: =IF(F12="","",((F12-MIN($F$6:$F$15))/(MAX($F$6:$F$15)-MIN($F$6:$F$15))*100)) -> 82.306778 | L12: =IF(E12="","",((E12-MIN($E$6:$E$15))/(MAX($E$6:$E$15)-MIN($E$6:$E$15))*100)) -> 58.100283 | M12: =IF(I12="","",((I12-MIN($I$6:$I$15))/(MAX($I$6:$I$15)-MIN($I$6:$I$15))*100)) -> 100 | N12: =IF(H12="","",100-((H12-MIN($H$6:$H$15))/(MAX($H$6:$H$15)-MIN($H$6:$H$15))*100)) -> 18.798154 | O12: =(IF(ISNUMBER(J12),J12,Inputs!$B$4)*INDEX(Inputs!$B$9:$F$13,MATCH(Inputs!$B$3,Inputs!$A$9:$A$13,0),1)+IF(ISNUMBER(K12),K12,Inputs!$B$4)*INDEX(Inputs!$B$9:$F$13,MATCH(Inputs!$B$3,Inputs!$A$9:$A$13,0),2)+IF(ISNUMBER(L12),L12,Inputs!$B$4)*INDEX(Inputs!$B$9:$F$13,MATCH(Inputs!$B$3,Inputs!$A$9:$A$13,0),3)+IF(ISNUMBER(M12),M12,Inputs!$B$4)*INDEX(Inputs!$B$9:$F$13,MATCH(Inputs!$B$3,Inputs!$A$9:$A$13,0),4)+IF(ISNUMBER(N12),N12,Inputs!$B$4)*INDEX(Inputs!$B$9:$F$13,MATCH(Inputs!$B$3,Inputs!$A$9:$A$13,0),5))/INDEX(Inputs!$G$9:$G$13,MATCH(Inputs!$B$3,Inputs!$A$9:$A$13,0)) -> 63.249496 | P12: =RANK(O12,$O$6:$O$15) -> 2 | Q12: =IF(P12<=Inputs!$B$5,"Lead",IF(P12<=Inputs!$B$6,"Grow","Selective")) -> Lead | R12: =IF(G12="","Growth only (credit neutral)","Growth + credit") -> Growth + credit
A13: Agribusiness | B13: =SUMIFS(GDP!$E$5:$E$21,GDP!$B$5:$B$21,$A13) -> 1920338 | C13: =B13/GDP!$E$22*100 -> 18.340612 | D13: =B13/SUMIFS(GDP!$D$5:$D$21,GDP!$B$5:$B$21,$A13)*100-100 -> 3.1042888 | E13: =((B13/SUMIFS(GDP!$C$5:$C$21,GDP!$B$5:$B$21,$A13))^(1/4)-1)*100 -> 3.0943363 | F13: =SUMIFS(GDP!$G$5:$G$21,GDP!$B$5:$B$21,$A13)/SUMIFS(GDP!$F$5:$F$21,GDP!$B$5:$B$21,$A13)*100-100 -> 4.9338745 | G13: =IF(SUMIFS(Credit_Map!$C$5:$C$15,Credit_Map!$A$5:$A$15,$A13)=0,"",SUMIFS(Credit_Map!$C$5:$C$15,Credit_Map!$A$5:$A$15,$A13)) -> 197895.5 | H13: =IF(G13="","",SUMIFS(Credit_Map!$D$5:$D$15,Credit_Map!$A$5:$A$15,$A13)/G13*100) -> 19.270069 | I13: =IF(G13="","",SUMPRODUCT((Credit_Map!$A$5:$A$15=$A13)*Credit_Map!$C$5:$C$15*(Credit_Map!$E$5:$E$15-Credit_Map!$F$5:$F$15))/G13) -> 19 | J13: =IF(B13="","",((B13-MIN($B$6:$B$15))/(MAX($B$6:$B$15)-MIN($B$6:$B$15))*100)) -> 100 | K13: =IF(F13="","",((F13-MIN($F$6:$F$15))/(MAX($F$6:$F$15)-MIN($F$6:$F$15))*100)) -> 49.83438 | L13: =IF(E13="","",((E13-MIN($E$6:$E$15))/(MAX($E$6:$E$15)-MIN($E$6:$E$15))*100)) -> 10.221731 | M13: =IF(I13="","",((I13-MIN($I$6:$I$15))/(MAX($I$6:$I$15)-MIN($I$6:$I$15))*100)) -> 24.355584 | N13: =IF(H13="","",100-((H13-MIN($H$6:$H$15))/(MAX($H$6:$H$15)-MIN($H$6:$H$15))*100)) -> 23.215433 | O13: =(IF(ISNUMBER(J13),J13,Inputs!$B$4)*INDEX(Inputs!$B$9:$F$13,MATCH(Inputs!$B$3,Inputs!$A$9:$A$13,0),1)+IF(ISNUMBER(K13),K13,Inputs!$B$4)*INDEX(Inputs!$B$9:$F$13,MATCH(Inputs!$B$3,Inputs!$A$9:$A$13,0),2)+IF(ISNUMBER(L13),L13,Inputs!$B$4)*INDEX(Inputs!$B$9:$F$13,MATCH(Inputs!$B$3,Inputs!$A$9:$A$13,0),3)+IF(ISNUMBER(M13),M13,Inputs!$B$4)*INDEX(Inputs!$B$9:$F$13,MATCH(Inputs!$B$3,Inputs!$A$9:$A$13,0),4)+IF(ISNUMBER(N13),N13,Inputs!$B$4)*INDEX(Inputs!$B$9:$F$13,MATCH(Inputs!$B$3,Inputs!$A$9:$A$13,0),5))/INDEX(Inputs!$G$9:$G$13,MATCH(Inputs!$B$3,Inputs!$A$9:$A$13,0)) -> 43.506058 | P13: =RANK(O13,$O$6:$O$15) -> 5 | Q13: =IF(P13<=Inputs!$B$5,"Lead",IF(P13<=Inputs!$B$6,"Grow","Selective")) -> Grow | R13: =IF(G13="","Growth only (credit neutral)","Growth + credit") -> Growth + credit
A14: Real Estate & Construction | B14: =SUMIFS(GDP!$E$5:$E$21,GDP!$B$5:$B$21,$A14) -> 1794502 | C14: =B14/GDP!$E$22*100 -> 17.138787 | D14: =B14/SUMIFS(GDP!$D$5:$D$21,GDP!$B$5:$B$21,$A14)*100-100 -> 4.8998615 | E14: =((B14/SUMIFS(GDP!$C$5:$C$21,GDP!$B$5:$B$21,$A14))^(1/4)-1)*100 -> 4.5163781 | F14: =SUMIFS(GDP!$G$5:$G$21,GDP!$B$5:$B$21,$A14)/SUMIFS(GDP!$F$5:$F$21,GDP!$B$5:$B$21,$A14)*100-100 -> 5.5021607 | G14: =IF(SUMIFS(Credit_Map!$C$5:$C$15,Credit_Map!$A$5:$A$15,$A14)=0,"",SUMIFS(Credit_Map!$C$5:$C$15,Credit_Map!$A$5:$A$15,$A14)) -> 686635.9 | H14: =IF(G14="","",SUMIFS(Credit_Map!$D$5:$D$15,Credit_Map!$A$5:$A$15,$A14)/G14*100) -> 24.112532 | I14: =IF(G14="","",SUMPRODUCT((Credit_Map!$A$5:$A$15=$A14)*Credit_Map!$C$5:$C$15*(Credit_Map!$E$5:$E$15-Credit_Map!$F$5:$F$15))/G14) -> 9.2024108 | J14: =IF(B14="","",((B14-MIN($B$6:$B$15))/(MAX($B$6:$B$15)-MIN($B$6:$B$15))*100)) -> 92.430476 | K14: =IF(F14="","",((F14-MIN($F$6:$F$15))/(MAX($F$6:$F$15)-MIN($F$6:$F$15))*100)) -> 71.038504 | L14: =IF(E14="","",((E14-MIN($E$6:$E$15))/(MAX($E$6:$E$15)-MIN($E$6:$E$15))*100)) -> 31.736669 | M14: =IF(I14="","",((I14-MIN($I$6:$I$15))/(MAX($I$6:$I$15)-MIN($I$6:$I$15))*100)) -> 2.6623106 | N14: =IF(H14="","",100-((H14-MIN($H$6:$H$15))/(MAX($H$6:$H$15)-MIN($H$6:$H$15))*100)) -> 0 | O14: =(IF(ISNUMBER(J14),J14,Inputs!$B$4)*INDEX(Inputs!$B$9:$F$13,MATCH(Inputs!$B$3,Inputs!$A$9:$A$13,0),1)+IF(ISNUMBER(K14),K14,Inputs!$B$4)*INDEX(Inputs!$B$9:$F$13,MATCH(Inputs!$B$3,Inputs!$A$9:$A$13,0),2)+IF(ISNUMBER(L14),L14,Inputs!$B$4)*INDEX(Inputs!$B$9:$F$13,MATCH(Inputs!$B$3,Inputs!$A$9:$A$13,0),3)+IF(ISNUMBER(M14),M14,Inputs!$B$4)*INDEX(Inputs!$B$9:$F$13,MATCH(Inputs!$B$3,Inputs!$A$9:$A$13,0),4)+IF(ISNUMBER(N14),N14,Inputs!$B$4)*INDEX(Inputs!$B$9:$F$13,MATCH(Inputs!$B$3,Inputs!$A$9:$A$13,0),5))/INDEX(Inputs!$G$9:$G$13,MATCH(Inputs!$B$3,Inputs!$A$9:$A$13,0)) -> 41.538684 | P14: =RANK(O14,$O$6:$O$15) -> 6 | Q14: =IF(P14<=Inputs!$B$5,"Lead",IF(P14<=Inputs!$B$6,"Grow","Selective")) -> Grow | R14: =IF(G14="","Growth only (credit neutral)","Growth + credit") -> Growth + credit
A15: Manufacturing | B15: =SUMIFS(GDP!$E$5:$E$21,GDP!$B$5:$B$21,$A15) -> 892166 | C15: =B15/GDP!$E$22*100 -> 8.5208283 | D15: =B15/SUMIFS(GDP!$D$5:$D$21,GDP!$B$5:$B$21,$A15)*100-100 -> 1.9762801 | E15: =((B15/SUMIFS(GDP!$C$5:$C$21,GDP!$B$5:$B$21,$A15))^(1/4)-1)*100 -> 2.4187254 | F15: =SUMIFS(GDP!$G$5:$G$21,GDP!$B$5:$B$21,$A15)/SUMIFS(GDP!$F$5:$F$21,GDP!$B$5:$B$21,$A15)*100-100 -> 4.4158346 | G15: =IF(SUMIFS(Credit_Map!$C$5:$C$15,Credit_Map!$A$5:$A$15,$A15)=0,"",SUMIFS(Credit_Map!$C$5:$C$15,Credit_Map!$A$5:$A$15,$A15)) -> 584989.3 | H15: =IF(G15="","",SUMIFS(Credit_Map!$D$5:$D$15,Credit_Map!$A$5:$A$15,$A15)/G15*100) -> 18.398559 | I15: =IF(G15="","",SUMPRODUCT((Credit_Map!$A$5:$A$15=$A15)*Credit_Map!$C$5:$C$15*(Credit_Map!$E$5:$E$15-Credit_Map!$F$5:$F$15))/G15) -> 30 | J15: =IF(B15="","",((B15-MIN($B$6:$B$15))/(MAX($B$6:$B$15)-MIN($B$6:$B$15))*100)) -> 38.151459 | K15: =IF(F15="","",((F15-MIN($F$6:$F$15))/(MAX($F$6:$F$15)-MIN($F$6:$F$15))*100)) -> 30.505068 | L15: =IF(E15="","",((E15-MIN($E$6:$E$15))/(MAX($E$6:$E$15)-MIN($E$6:$E$15))*100)) -> 0 | M15: =IF(I15="","",((I15-MIN($I$6:$I$15))/(MAX($I$6:$I$15)-MIN($I$6:$I$15))*100)) -> 48.711168 | N15: =IF(H15="","",100-((H15-MIN($H$6:$H$15))/(MAX($H$6:$H$15)-MIN($H$6:$H$15))*100)) -> 27.393575 | O15: =(IF(ISNUMBER(J15),J15,Inputs!$B$4)*INDEX(Inputs!$B$9:$F$13,MATCH(Inputs!$B$3,Inputs!$A$9:$A$13,0),1)+IF(ISNUMBER(K15),K15,Inputs!$B$4)*INDEX(Inputs!$B$9:$F$13,MATCH(Inputs!$B$3,Inputs!$A$9:$A$13,0),2)+IF(ISNUMBER(L15),L15,Inputs!$B$4)*INDEX(Inputs!$B$9:$F$13,MATCH(Inputs!$B$3,Inputs!$A$9:$A$13,0),3)+IF(ISNUMBER(M15),M15,Inputs!$B$4)*INDEX(Inputs!$B$9:$F$13,MATCH(Inputs!$B$3,Inputs!$A$9:$A$13,0),4)+IF(ISNUMBER(N15),N15,Inputs!$B$4)*INDEX(Inputs!$B$9:$F$13,MATCH(Inputs!$B$3,Inputs!$A$9:$A$13,0),5))/INDEX(Inputs!$G$9:$G$13,MATCH(Inputs!$B$3,Inputs!$A$9:$A$13,0)) -> 30.477508 | P15: =RANK(O15,$O$6:$O$15) -> 9 | Q15: =IF(P15<=Inputs!$B$5,"Lead",IF(P15<=Inputs!$B$6,"Grow","Selective")) -> Selective | R15: =IF(G15="","Growth only (credit neutral)","Growth + credit") -> Growth + credit
A37: Reading the table: growth and size say where the economy is moving; credit demand and NPLs say where banks see client activity and risk. Public Sector and Health have no matching bank sector, so their credit pillars are neutral.

Sheet Scenarios
A1: Scores and ranks under five weighting scenarios
A2: A robust priority stays near the top whatever the weights. Rank range shows sensitivity.
A4: Industry group | B4: Score: Balanced | C4: Score: Growth-led | D4: Score: Risk-aware | E4: Score: Scale-led | F4: Score: Equal | G4: Rank: Balanced | H4: Rank: Growth-led | I4: Rank: Risk-aware | J4: Rank: Scale-led | K4: Rank: Equal | L4: Best rank | M4: Worst rank | N4: Stability
A5: =Scorecard!A6 -> Financial Services | B5: =(IF(ISNUMBER(Scorecard!J6),Scorecard!J6,Inputs!$B$4)*Inputs!B$9+IF(ISNUMBER(Scorecard!K6),Scorecard!K6,Inputs!$B$4)*Inputs!C$9+IF(ISNUMBER(Scorecard!L6),Scorecard!L6,Inputs!$B$4)*Inputs!D$9+IF(ISNUMBER(Scorecard!M6),Scorecard!M6,Inputs!$B$4)*Inputs!E$9+IF(ISNUMBER(Scorecard!N6),Scorecard!N6,Inputs!$B$4)*Inputs!F$9)/Inputs!$G$9 -> 76.746877 | C5: =(IF(ISNUMBER(Scorecard!J6),Scorecard!J6,Inputs!$B$4)*Inputs!B$10+IF(ISNUMBER(Scorecard!K6),Scorecard!K6,Inputs!$B$4)*Inputs!C$10+IF(ISNUMBER(Scorecard!L6),Scorecard!L6,Inputs!$B$4)*Inputs!D$10+IF(ISNUMBER(Scorecard!M6),Scorecard!M6,Inputs!$B$4)*Inputs!E$10+IF(ISNUMBER(Scorecard!N6),Scorecard!N6,Inputs!$B$4)*Inputs!F$10)/Inputs!$G$10 -> 81.47324 | D5: =(IF(ISNUMBER(Scorecard!J6),Scorecard!J6,Inputs!$B$4)*Inputs!B$11+IF(ISNUMBER(Scorecard!K6),Scorecard!K6,Inputs!$B$4)*Inputs!C$11+IF(ISNUMBER(Scorecard!L6),Scorecard!L6,Inputs!$B$4)*Inputs!D$11+IF(ISNUMBER(Scorecard!M6),Scorecard!M6,Inputs!$B$4)*Inputs!E$11+IF(ISNUMBER(Scorecard!N6),Scorecard!N6,Inputs!$B$4)*Inputs!F$11)/Inputs!$G$11 -> 80.196976 | E5: =(IF(ISNUMBER(Scorecard!J6),Scorecard!J6,Inputs!$B$4)*Inputs!B$12+IF(ISNUMBER(Scorecard!K6),Scorecard!K6,Inputs!$B$4)*Inputs!C$12+IF(ISNUMBER(Scorecard!L6),Scorecard!L6,Inputs!$B$4)*Inputs!D$12+IF(ISNUMBER(Scorecard!M6),Scorecard!M6,Inputs!$B$4)*Inputs!E$12+IF(ISNUMBER(Scorecard!N6),Scorecard!N6,Inputs!$B$4)*Inputs!F$12)/Inputs!$G$12 -> 68.381069 | F5: =(IF(ISNUMBER(Scorecard!J6),Scorecard!J6,Inputs!$B$4)*Inputs!B$13+IF(ISNUMBER(Scorecard!K6),Scorecard!K6,Inputs!$B$4)*Inputs!C$13+IF(ISNUMBER(Scorecard!L6),Scorecard!L6,Inputs!$B$4)*Inputs!D$13+IF(ISNUMBER(Scorecard!M6),Scorecard!M6,Inputs!$B$4)*Inputs!E$13+IF(ISNUMBER(Scorecard!N6),Scorecard!N6,Inputs!$B$4)*Inputs!F$13)/Inputs!$G$13 -> 76.746877 | G5: =RANK(B5,B$5:B$14) -> 1 | H5: =RANK(C5,C$5:C$14) -> 1 | I5: =RANK(D5,D$5:D$14) -> 1 | J5: =RANK(E5,E$5:E$14) -> 1 | K5: =RANK(F5,F$5:F$14) -> 1 | L5: =MIN(G5:K5) -> 1 | M5: =MAX(G5:K5) -> 1 | N5: =IF(M5-L5<=3,"Stable","Sensitive") -> Stable
A6: =Scorecard!A7 -> Energy & Resources | B6: =(IF(ISNUMBER(Scorecard!J7),Scorecard!J7,Inputs!$B$4)*Inputs!B$9+IF(ISNUMBER(Scorecard!K7),Scorecard!K7,Inputs!$B$4)*Inputs!C$9+IF(ISNUMBER(Scorecard!L7),Scorecard!L7,Inputs!$B$4)*Inputs!D$9+IF(ISNUMBER(Scorecard!M7),Scorecard!M7,Inputs!$B$4)*Inputs!E$9+IF(ISNUMBER(Scorecard!N7),Scorecard!N7,Inputs!$B$4)*Inputs!F$9)/Inputs!$G$9 -> 45.253634 | C6: =(IF(ISNUMBER(Scorecard!J7),Scorecard!J7,Inputs!$B$4)*Inputs!B$10+IF(ISNUMBER(Scorecard!K7),Scorecard!K7,Inputs!$B$4)*Inputs!C$10+IF(ISNUMBER(Scorecard!L7),Scorecard!L7,Inputs!$B$4)*Inputs!D$10+IF(ISNUMBER(Scorecard!M7),Scorecard!M7,Inputs!$B$4)*Inputs!E$10+IF(ISNUMBER(Scorecard!N7),Scorecard!N7,Inputs!$B$4)*Inputs!F$10)/Inputs!$G$10 -> 46.880818 | D6: =(IF(ISNUMBER(Scorecard!J7),Scorecard!J7,Inputs!$B$4)*Inputs!B$11+IF(ISNUMBER(Scorecard!K7),Scorecard!K7,Inputs!$B$4)*Inputs!C$11+IF(ISNUMBER(Scorecard!L7),Scorecard!L7,Inputs!$B$4)*Inputs!D$11+IF(ISNUMBER(Scorecard!M7),Scorecard!M7,Inputs!$B$4)*Inputs!E$11+IF(ISNUMBER(Scorecard!N7),Scorecard!N7,Inputs!$B$4)*Inputs!F$11)/Inputs!$G$11 -> 48.662768 | E6: =(IF(ISNUMBER(Scorecard!J7),Scorecard!J7,Inputs!$B$4)*Inputs!B$12+IF(ISNUMBER(Scorecard!K7),Scorecard!K7,Inputs!$B$4)*Inputs!C$12+IF(ISNUMBER(Scorecard!L7),Scorecard!L7,Inputs!$B$4)*Inputs!D$12+IF(ISNUMBER(Scorecard!M7),Scorecard!M7,Inputs!$B$4)*Inputs!E$12+IF(ISNUMBER(Scorecard!N7),Scorecard!N7,Inputs!$B$4)*Inputs!F$12)/Inputs!$G$12 -> 33.127225 | F6: =(IF(ISNUMBER(Scorecard!J7),Scorecard!J7,Inputs!$B$4)*Inputs!B$13+IF(ISNUMBER(Scorecard!K7),Scorecard!K7,Inputs!$B$4)*Inputs!C$13+IF(ISNUMBER(Scorecard!L7),Scorecard!L7,Inputs!$B$4)*Inputs!D$13+IF(ISNUMBER(Scorecard!M7),Scorecard!M7,Inputs!$B$4)*Inputs!E$13+IF(ISNUMBER(Scorecard!N7),Scorecard!N7,Inputs!$B$4)*Inputs!F$13)/Inputs!$G$13 -> 42.197172 | G6: =RANK(B6,B$5:B$14) -> 4 | H6: =RANK(C6,C$5:C$14) -> 4 | I6: =RANK(D6,D$5:D$14) -> 4 | J6: =RANK(E6,E$5:E$14) -> 7 | K6: =RANK(F6,F$5:F$14) -> 4 | L6: =MIN(G6:K6) -> 4 | M6: =MAX(G6:K6) -> 7 | N6: =IF(M6-L6<=3,"Stable","Sensitive") -> Stable
A7: =Scorecard!A8 -> Technology, Media & Telecom | B7: =(IF(ISNUMBER(Scorecard!J8),Scorecard!J8,Inputs!$B$4)*Inputs!B$9+IF(ISNUMBER(Scorecard!K8),Scorecard!K8,Inputs!$B$4)*Inputs!C$9+IF(ISNUMBER(Scorecard!L8),Scorecard!L8,Inputs!$B$4)*Inputs!D$9+IF(ISNUMBER(Scorecard!M8),Scorecard!M8,Inputs!$B$4)*Inputs!E$9+IF(ISNUMBER(Scorecard!N8),Scorecard!N8,Inputs!$B$4)*Inputs!F$9)/Inputs!$G$9 -> 33.893572 | C7: =(IF(ISNUMBER(Scorecard!J8),Scorecard!J8,Inputs!$B$4)*Inputs!B$10+IF(ISNUMBER(Scorecard!K8),Scorecard!K8,Inputs!$B$4)*Inputs!C$10+IF(ISNUMBER(Scorecard!L8),Scorecard!L8,Inputs!$B$4)*Inputs!D$10+IF(ISNUMBER(Scorecard!M8),Scorecard!M8,Inputs!$B$4)*Inputs!E$10+IF(ISNUMBER(Scorecard!N8),Scorecard!N8,Inputs!$B$4)*Inputs!F$10)/Inputs!$G$10 -> 42.739605 | D7: =(IF(ISNUMBER(Scorecard!J8),Scorecard!J8,Inputs!$B$4)*Inputs!B$11+IF(ISNUMBER(Scorecard!K8),Scorecard!K8,Inputs!$B$4)*Inputs!C$11+IF(ISNUMBER(Scorecard!L8),Scorecard!L8,Inputs!$B$4)*Inputs!D$11+IF(ISNUMBER(Scorecard!M8),Scorecard!M8,Inputs!$B$4)*Inputs!E$11+IF(ISNUMBER(Scorecard!N8),Scorecard!N8,Inputs!$B$4)*Inputs!F$11)/Inputs!$G$11 -> 31.930236 | E7: =(IF(ISNUMBER(Scorecard!J8),Scorecard!J8,Inputs!$B$4)*Inputs!B$12+IF(ISNUMBER(Scorecard!K8),Scorecard!K8,Inputs!$B$4)*Inputs!C$12+IF(ISNUMBER(Scorecard!L8),Scorecard!L8,Inputs!$B$4)*Inputs!D$12+IF(ISNUMBER(Scorecard!M8),Scorecard!M8,Inputs!$B$4)*Inputs!E$12+IF(ISNUMBER(Scorecard!N8),Scorecard!N8,Inputs!$B$4)*Inputs!F$12)/Inputs!$G$12 -> 24.89486 | F7: =(IF(ISNUMBER(Scorecard!J8),Scorecard!J8,Inputs!$B$4)*Inputs!B$13+IF(ISNUMBER(Scorecard!K8),Scorecard!K8,Inputs!$B$4)*Inputs!C$13+IF(ISNUMBER(Scorecard!L8),Scorecard!L8,Inputs!$B$4)*Inputs!D$13+IF(ISNUMBER(Scorecard!M8),Scorecard!M8,Inputs!$B$4)*Inputs!E$13+IF(ISNUMBER(Scorecard!N8),Scorecard!N8,Inputs!$B$4)*Inputs!F$13)/Inputs!$G$13 -> 35.394807 | G7: =RANK(B7,B$5:B$14) -> 7 | H7: =RANK(C7,C$5:C$14) -> 5 | I7: =RANK(D7,D$5:D$14) -> 8 | J7: =RANK(E7,E$5:E$14) -> 9 | K7: =RANK(F7,F$5:F$14) -> 7 | L7: =MIN(G7:K7) -> 5 | M7: =MAX(G7:K7) -> 9 | N7: =IF(M7-L7<=3,"Stable","Sensitive") -> Sensitive
A8: =Scorecard!A9 -> Transport & Logistics | B8: =(IF(ISNUMBER(Scorecard!J9),Scorecard!J9,Inputs!$B$4)*Inputs!B$9+IF(ISNUMBER(Scorecard!K9),Scorecard!K9,Inputs!$B$4)*Inputs!C$9+IF(ISNUMBER(Scorecard!L9),Scorecard!L9,Inputs!$B$4)*Inputs!D$9+IF(ISNUMBER(Scorecard!M9),Scorecard!M9,Inputs!$B$4)*Inputs!E$9+IF(ISNUMBER(Scorecard!N9),Scorecard!N9,Inputs!$B$4)*Inputs!F$9)/Inputs!$G$9 -> 22.56725 | C8: =(IF(ISNUMBER(Scorecard!J9),Scorecard!J9,Inputs!$B$4)*Inputs!B$10+IF(ISNUMBER(Scorecard!K9),Scorecard!K9,Inputs!$B$4)*Inputs!C$10+IF(ISNUMBER(Scorecard!L9),Scorecard!L9,Inputs!$B$4)*Inputs!D$10+IF(ISNUMBER(Scorecard!M9),Scorecard!M9,Inputs!$B$4)*Inputs!E$10+IF(ISNUMBER(Scorecard!N9),Scorecard!N9,Inputs!$B$4)*Inputs!F$10)/Inputs!$G$10 -> 17.666664 | D8: =(IF(ISNUMBER(Scorecard!J9),Scorecard!J9,Inputs!$B$4)*Inputs!B$11+IF(ISNUMBER(Scorecard!K9),Scorecard!K9,Inputs!$B$4)*Inputs!C$11+IF(ISNUMBER(Scorecard!L9),Scorecard!L9,Inputs!$B$4)*Inputs!D$11+IF(ISNUMBER(Scorecard!M9),Scorecard!M9,Inputs!$B$4)*Inputs!E$11+IF(ISNUMBER(Scorecard!N9),Scorecard!N9,Inputs!$B$4)*Inputs!F$11)/Inputs!$G$11 -> 27.98336 | E8: =(IF(ISNUMBER(Scorecard!J9),Scorecard!J9,Inputs!$B$4)*Inputs!B$12+IF(ISNUMBER(Scorecard!K9),Scorecard!K9,Inputs!$B$4)*Inputs!C$12+IF(ISNUMBER(Scorecard!L9),Scorecard!L9,Inputs!$B$4)*Inputs!D$12+IF(ISNUMBER(Scorecard!M9),Scorecard!M9,Inputs!$B$4)*Inputs!E$12+IF(ISNUMBER(Scorecard!N9),Scorecard!N9,Inputs!$B$4)*Inputs!F$12)/Inputs!$G$12 -> 31.253863 | F8: =(IF(ISNUMBER(Scorecard!J9),Scorecard!J9,Inputs!$B$4)*Inputs!B$13+IF(ISNUMBER(Scorecard!K9),Scorecard!K9,Inputs!$B$4)*Inputs!C$13+IF(ISNUMBER(Scorecard!L9),Scorecard!L9,Inputs!$B$4)*Inputs!D$13+IF(ISNUMBER(Scorecard!M9),Scorecard!M9,Inputs!$B$4)*Inputs!E$13+IF(ISNUMBER(Scorecard!N9),Scorecard!N9,Inputs!$B$4)*Inputs!F$13)/Inputs!$G$13 -> 24.390975 | G8: =RANK(B8,B$5:B$14) -> 10 | H8: =RANK(C8,C$5:C$14) -> 10 | I8: =RANK(D8,D$5:D$14) -> 10 | J8: =RANK(E8,E$5:E$14) -> 8 | K8: =RANK(F8,F$5:F$14) -> 10 | L8: =MIN(G8:K8) -> 8 | M8: =MAX(G8:K8) -> 10 | N8: =IF(M8-L8<=3,"Stable","Sensitive") -> Stable
A9: =Scorecard!A10 -> Public Sector & Development | B9: =(IF(ISNUMBER(Scorecard!J10),Scorecard!J10,Inputs!$B$4)*Inputs!B$9+IF(ISNUMBER(Scorecard!K10),Scorecard!K10,Inputs!$B$4)*Inputs!C$9+IF(ISNUMBER(Scorecard!L10),Scorecard!L10,Inputs!$B$4)*Inputs!D$9+IF(ISNUMBER(Scorecard!M10),Scorecard!M10,Inputs!$B$4)*Inputs!E$9+IF(ISNUMBER(Scorecard!N10),Scorecard!N10,Inputs!$B$4)*Inputs!F$9)/Inputs!$G$9 -> 60.810548 | C9: =(IF(ISNUMBER(Scorecard!J10),Scorecard!J10,Inputs!$B$4)*Inputs!B$10+IF(ISNUMBER(Scorecard!K10),Scorecard!K10,Inputs!$B$4)*Inputs!C$10+IF(ISNUMBER(Scorecard!L10),Scorecard!L10,Inputs!$B$4)*Inputs!D$10+IF(ISNUMBER(Scorecard!M10),Scorecard!M10,Inputs!$B$4)*Inputs!E$10+IF(ISNUMBER(Scorecard!N10),Scorecard!N10,Inputs!$B$4)*Inputs!F$10)/Inputs!$G$10 -> 63.015984 | D9: =(IF(ISNUMBER(Scorecard!J10),Scorecard!J10,Inputs!$B$4)*Inputs!B$11+IF(ISNUMBER(Scorecard!K10),Scorecard!K10,Inputs!$B$4)*Inputs!C$11+IF(ISNUMBER(Scorecard!L10),Scorecard!L10,Inputs!$B$4)*Inputs!D$11+IF(ISNUMBER(Scorecard!M10),Scorecard!M10,Inputs!$B$4)*Inputs!E$11+IF(ISNUMBER(Scorecard!N10),Scorecard!N10,Inputs!$B$4)*Inputs!F$11)/Inputs!$G$11 -> 57.343703 | E9: =(IF(ISNUMBER(Scorecard!J10),Scorecard!J10,Inputs!$B$4)*Inputs!B$12+IF(ISNUMBER(Scorecard!K10),Scorecard!K10,Inputs!$B$4)*Inputs!C$12+IF(ISNUMBER(Scorecard!L10),Scorecard!L10,Inputs!$B$4)*Inputs!D$12+IF(ISNUMBER(Scorecard!M10),Scorecard!M10,Inputs!$B$4)*Inputs!E$12+IF(ISNUMBER(Scorecard!N10),Scorecard!N10,Inputs!$B$4)*Inputs!F$12)/Inputs!$G$12 -> 60.117842 | F9: =(IF(ISNUMBER(Scorecard!J10),Scorecard!J10,Inputs!$B$4)*Inputs!B$13+IF(ISNUMBER(Scorecard!K10),Scorecard!K10,Inputs!$B$4)*Inputs!C$13+IF(ISNUMBER(Scorecard!L10),Scorecard!L10,Inputs!$B$4)*Inputs!D$13+IF(ISNUMBER(Scorecard!M10),Scorecard!M10,Inputs!$B$4)*Inputs!E$13+IF(ISNUMBER(Scorecard!N10),Scorecard!N10,Inputs!$B$4)*Inputs!F$13)/Inputs!$G$13 -> 58.849495 | G9: =RANK(B9,B$5:B$14) -> 3 | H9: =RANK(C9,C$5:C$14) -> 3 | I9: =RANK(D9,D$5:D$14) -> 2 | J9: =RANK(E9,E$5:E$14) -> 3 | K9: =RANK(F9,F$5:F$14) -> 3 | L9: =MIN(G9:K9) -> 2 | M9: =MAX(G9:K9) -> 3 | N9: =IF(M9-L9<=3,"Stable","Sensitive") -> Stable
A10: =Scorecard!A11 -> Health | B10: =(IF(ISNUMBER(Scorecard!J11),Scorecard!J11,Inputs!$B$4)*Inputs!B$9+IF(ISNUMBER(Scorecard!K11),Scorecard!K11,Inputs!$B$4)*Inputs!C$9+IF(ISNUMBER(Scorecard!L11),Scorecard!L11,Inputs!$B$4)*Inputs!D$9+IF(ISNUMBER(Scorecard!M11),Scorecard!M11,Inputs!$B$4)*Inputs!E$9+IF(ISNUMBER(Scorecard!N11),Scorecard!N11,Inputs!$B$4)*Inputs!F$9)/Inputs!$G$9 -> 32.136989 | C10: =(IF(ISNUMBER(Scorecard!J11),Scorecard!J11,Inputs!$B$4)*Inputs!B$10+IF(ISNUMBER(Scorecard!K11),Scorecard!K11,Inputs!$B$4)*Inputs!C$10+IF(ISNUMBER(Scorecard!L11),Scorecard!L11,Inputs!$B$4)*Inputs!D$10+IF(ISNUMBER(Scorecard!M11),Scorecard!M11,Inputs!$B$4)*Inputs!E$10+IF(ISNUMBER(Scorecard!N11),Scorecard!N11,Inputs!$B$4)*Inputs!F$10)/Inputs!$G$10 -> 33.455106 | D10: =(IF(ISNUMBER(Scorecard!J11),Scorecard!J11,Inputs!$B$4)*Inputs!B$11+IF(ISNUMBER(Scorecard!K11),Scorecard!K11,Inputs!$B$4)*Inputs!C$11+IF(ISNUMBER(Scorecard!L11),Scorecard!L11,Inputs!$B$4)*Inputs!D$11+IF(ISNUMBER(Scorecard!M11),Scorecard!M11,Inputs!$B$4)*Inputs!E$11+IF(ISNUMBER(Scorecard!N11),Scorecard!N11,Inputs!$B$4)*Inputs!F$11)/Inputs!$G$11 -> 35.148024 | E10: =(IF(ISNUMBER(Scorecard!J11),Scorecard!J11,Inputs!$B$4)*Inputs!B$12+IF(ISNUMBER(Scorecard!K11),Scorecard!K11,Inputs!$B$4)*Inputs!C$12+IF(ISNUMBER(Scorecard!L11),Scorecard!L11,Inputs!$B$4)*Inputs!D$12+IF(ISNUMBER(Scorecard!M11),Scorecard!M11,Inputs!$B$4)*Inputs!E$12+IF(ISNUMBER(Scorecard!N11),Scorecard!N11,Inputs!$B$4)*Inputs!F$12)/Inputs!$G$12 -> 22.648024 | F10: =(IF(ISNUMBER(Scorecard!J11),Scorecard!J11,Inputs!$B$4)*Inputs!B$13+IF(ISNUMBER(Scorecard!K11),Scorecard!K11,Inputs!$B$4)*Inputs!C$13+IF(ISNUMBER(Scorecard!L11),Scorecard!L11,Inputs!$B$4)*Inputs!D$13+IF(ISNUMBER(Scorecard!M11),Scorecard!M11,Inputs!$B$4)*Inputs!E$13+IF(ISNUMBER(Scorecard!N11),Scorecard!N11,Inputs!$B$4)*Inputs!F$13)/Inputs!$G$13 -> 32.636235 | G10: =RANK(B10,B$5:B$14) -> 8 | H10: =RANK(C10,C$5:C$14) -> 8 | I10: =RANK(D10,D$5:D$14) -> 6 | J10: =RANK(E10,E$5:E$14) -> 10 | K10: =RANK(F10,F$5:F$14) -> 8 | L10: =MIN(G10:K10) -> 6 | M10: =MAX(G10:K10) -> 10 | N10: =IF(M10-L10<=3,"Stable","Sensitive") -> Sensitive
A11: =Scorecard!A12 -> Consumer & Retail | B11: =(IF(ISNUMBER(Scorecard!J12),Scorecard!J12,Inputs!$B$4)*Inputs!B$9+IF(ISNUMBER(Scorecard!K12),Scorecard!K12,Inputs!$B$4)*Inputs!C$9+IF(ISNUMBER(Scorecard!L12),Scorecard!L12,Inputs!$B$4)*Inputs!D$9+IF(ISNUMBER(Scorecard!M12),Scorecard!M12,Inputs!$B$4)*Inputs!E$9+IF(ISNUMBER(Scorecard!N12),Scorecard!N12,Inputs!$B$4)*Inputs!F$9)/Inputs!$G$9 -> 63.249496 | C11: =(IF(ISNUMBER(Scorecard!J12),Scorecard!J12,Inputs!$B$4)*Inputs!B$10+IF(ISNUMBER(Scorecard!K12),Scorecard!K12,Inputs!$B$4)*Inputs!C$10+IF(ISNUMBER(Scorecard!L12),Scorecard!L12,Inputs!$B$4)*Inputs!D$10+IF(ISNUMBER(Scorecard!M12),Scorecard!M12,Inputs!$B$4)*Inputs!E$10+IF(ISNUMBER(Scorecard!N12),Scorecard!N12,Inputs!$B$4)*Inputs!F$10)/Inputs!$G$10 -> 70.311323 | D11: =(IF(ISNUMBER(Scorecard!J12),Scorecard!J12,Inputs!$B$4)*Inputs!B$11+IF(ISNUMBER(Scorecard!K12),Scorecard!K12,Inputs!$B$4)*Inputs!C$11+IF(ISNUMBER(Scorecard!L12),Scorecard!L12,Inputs!$B$4)*Inputs!D$11+IF(ISNUMBER(Scorecard!M12),Scorecard!M12,Inputs!$B$4)*Inputs!E$11+IF(ISNUMBER(Scorecard!N12),Scorecard!N12,Inputs!$B$4)*Inputs!F$11)/Inputs!$G$11 -> 50.873435 | E11: =(IF(ISNUMBER(Scorecard!J12),Scorecard!J12,Inputs!$B$4)*Inputs!B$12+IF(ISNUMBER(Scorecard!K12),Scorecard!K12,Inputs!$B$4)*Inputs!C$12+IF(ISNUMBER(Scorecard!L12),Scorecard!L12,Inputs!$B$4)*Inputs!D$12+IF(ISNUMBER(Scorecard!M12),Scorecard!M12,Inputs!$B$4)*Inputs!E$12+IF(ISNUMBER(Scorecard!N12),Scorecard!N12,Inputs!$B$4)*Inputs!F$12)/Inputs!$G$12 -> 58.921558 | F11: =(IF(ISNUMBER(Scorecard!J12),Scorecard!J12,Inputs!$B$4)*Inputs!B$13+IF(ISNUMBER(Scorecard!K12),Scorecard!K12,Inputs!$B$4)*Inputs!C$13+IF(ISNUMBER(Scorecard!L12),Scorecard!L12,Inputs!$B$4)*Inputs!D$13+IF(ISNUMBER(Scorecard!M12),Scorecard!M12,Inputs!$B$4)*Inputs!E$13+IF(ISNUMBER(Scorecard!N12),Scorecard!N12,Inputs!$B$4)*Inputs!F$13)/Inputs!$G$13 -> 62.039172 | G11: =RANK(B11,B$5:B$14) -> 2 | H11: =RANK(C11,C$5:C$14) -> 2 | I11: =RANK(D11,D$5:D$14) -> 3 | J11: =RANK(E11,E$5:E$14) -> 4 | K11: =RANK(F11,F$5:F$14) -> 2 | L11: =MIN(G11:K11) -> 2 | M11: =MAX(G11:K11) -> 4 | N11: =IF(M11-L11<=3,"Stable","Sensitive") -> Stable
A12: =Scorecard!A13 -> Agribusiness | B12: =(IF(ISNUMBER(Scorecard!J13),Scorecard!J13,Inputs!$B$4)*Inputs!B$9+IF(ISNUMBER(Scorecard!K13),Scorecard!K13,Inputs!$B$4)*Inputs!C$9+IF(ISNUMBER(Scorecard!L13),Scorecard!L13,Inputs!$B$4)*Inputs!D$9+IF(ISNUMBER(Scorecard!M13),Scorecard!M13,Inputs!$B$4)*Inputs!E$9+IF(ISNUMBER(Scorecard!N13),Scorecard!N13,Inputs!$B$4)*Inputs!F$9)/Inputs!$G$9 -> 43.506058 | C12: =(IF(ISNUMBER(Scorecard!J13),Scorecard!J13,Inputs!$B$4)*Inputs!B$10+IF(ISNUMBER(Scorecard!K13),Scorecard!K13,Inputs!$B$4)*Inputs!C$10+IF(ISNUMBER(Scorecard!L13),Scorecard!L13,Inputs!$B$4)*Inputs!D$10+IF(ISNUMBER(Scorecard!M13),Scorecard!M13,Inputs!$B$4)*Inputs!E$10+IF(ISNUMBER(Scorecard!N13),Scorecard!N13,Inputs!$B$4)*Inputs!F$10)/Inputs!$G$10 -> 37.190126 | D12: =(IF(ISNUMBER(Scorecard!J13),Scorecard!J13,Inputs!$B$4)*Inputs!B$11+IF(ISNUMBER(Scorecard!K13),Scorecard!K13,Inputs!$B$4)*Inputs!C$11+IF(ISNUMBER(Scorecard!L13),Scorecard!L13,Inputs!$B$4)*Inputs!D$11+IF(ISNUMBER(Scorecard!M13),Scorecard!M13,Inputs!$B$4)*Inputs!E$11+IF(ISNUMBER(Scorecard!N13),Scorecard!N13,Inputs!$B$4)*Inputs!F$11)/Inputs!$G$11 -> 41.436841 | E12: =(IF(ISNUMBER(Scorecard!J13),Scorecard!J13,Inputs!$B$4)*Inputs!B$12+IF(ISNUMBER(Scorecard!K13),Scorecard!K13,Inputs!$B$4)*Inputs!C$12+IF(ISNUMBER(Scorecard!L13),Scorecard!L13,Inputs!$B$4)*Inputs!D$12+IF(ISNUMBER(Scorecard!M13),Scorecard!M13,Inputs!$B$4)*Inputs!E$12+IF(ISNUMBER(Scorecard!N13),Scorecard!N13,Inputs!$B$4)*Inputs!F$12)/Inputs!$G$12 -> 60.632983 | F12: =(IF(ISNUMBER(Scorecard!J13),Scorecard!J13,Inputs!$B$4)*Inputs!B$13+IF(ISNUMBER(Scorecard!K13),Scorecard!K13,Inputs!$B$4)*Inputs!C$13+IF(ISNUMBER(Scorecard!L13),Scorecard!L13,Inputs!$B$4)*Inputs!D$13+IF(ISNUMBER(Scorecard!M13),Scorecard!M13,Inputs!$B$4)*Inputs!E$13+IF(ISNUMBER(Scorecard!N13),Scorecard!N13,Inputs!$B$4)*Inputs!F$13)/Inputs!$G$13 -> 41.525426 | G12: =RANK(B12,B$5:B$14) -> 5 | H12: =RANK(C12,C$5:C$14) -> 7 | I12: =RANK(D12,D$5:D$14) -> 5 | J12: =RANK(E12,E$5:E$14) -> 2 | K12: =RANK(F12,F$5:F$14) -> 5 | L12: =MIN(G12:K12) -> 2 | M12: =MAX(G12:K12) -> 7 | N12: =IF(M12-L12<=3,"Stable","Sensitive") -> Sensitive
A13: =Scorecard!A14 -> Real Estate & Construction | B13: =(IF(ISNUMBER(Scorecard!J14),Scorecard!J14,Inputs!$B$4)*Inputs!B$9+IF(ISNUMBER(Scorecard!K14),Scorecard!K14,Inputs!$B$4)*Inputs!C$9+IF(ISNUMBER(Scorecard!L14),Scorecard!L14,Inputs!$B$4)*Inputs!D$9+IF(ISNUMBER(Scorecard!M14),Scorecard!M14,Inputs!$B$4)*Inputs!E$9+IF(ISNUMBER(Scorecard!N14),Scorecard!N14,Inputs!$B$4)*Inputs!F$9)/Inputs!$G$9 -> 41.538684 | C13: =(IF(ISNUMBER(Scorecard!J14),Scorecard!J14,Inputs!$B$4)*Inputs!B$10+IF(ISNUMBER(Scorecard!K14),Scorecard!K14,Inputs!$B$4)*Inputs!C$10+IF(ISNUMBER(Scorecard!L14),Scorecard!L14,Inputs!$B$4)*Inputs!D$10+IF(ISNUMBER(Scorecard!M14),Scorecard!M14,Inputs!$B$4)*Inputs!E$10+IF(ISNUMBER(Scorecard!N14),Scorecard!N14,Inputs!$B$4)*Inputs!F$10)/Inputs!$G$10 -> 42.573153 | D13: =(IF(ISNUMBER(Scorecard!J14),Scorecard!J14,Inputs!$B$4)*Inputs!B$11+IF(ISNUMBER(Scorecard!K14),Scorecard!K14,Inputs!$B$4)*Inputs!C$11+IF(ISNUMBER(Scorecard!L14),Scorecard!L14,Inputs!$B$4)*Inputs!D$11+IF(ISNUMBER(Scorecard!M14),Scorecard!M14,Inputs!$B$4)*Inputs!E$11+IF(ISNUMBER(Scorecard!N14),Scorecard!N14,Inputs!$B$4)*Inputs!F$11)/Inputs!$G$11 -> 32.714884 | E13: =(IF(ISNUMBER(Scorecard!J14),Scorecard!J14,Inputs!$B$4)*Inputs!B$12+IF(ISNUMBER(Scorecard!K14),Scorecard!K14,Inputs!$B$4)*Inputs!C$12+IF(ISNUMBER(Scorecard!L14),Scorecard!L14,Inputs!$B$4)*Inputs!D$12+IF(ISNUMBER(Scorecard!M14),Scorecard!M14,Inputs!$B$4)*Inputs!E$12+IF(ISNUMBER(Scorecard!N14),Scorecard!N14,Inputs!$B$4)*Inputs!F$12)/Inputs!$G$12 -> 55.822503 | F13: =(IF(ISNUMBER(Scorecard!J14),Scorecard!J14,Inputs!$B$4)*Inputs!B$13+IF(ISNUMBER(Scorecard!K14),Scorecard!K14,Inputs!$B$4)*Inputs!C$13+IF(ISNUMBER(Scorecard!L14),Scorecard!L14,Inputs!$B$4)*Inputs!D$13+IF(ISNUMBER(Scorecard!M14),Scorecard!M14,Inputs!$B$4)*Inputs!E$13+IF(ISNUMBER(Scorecard!N14),Scorecard!N14,Inputs!$B$4)*Inputs!F$13)/Inputs!$G$13 -> 39.573592 | G13: =RANK(B13,B$5:B$14) -> 6 | H13: =RANK(C13,C$5:C$14) -> 6 | I13: =RANK(D13,D$5:D$14) -> 7 | J13: =RANK(E13,E$5:E$14) -> 5 | K13: =RANK(F13,F$5:F$14) -> 6 | L13: =MIN(G13:K13) -> 5 | M13: =MAX(G13:K13) -> 7 | N13: =IF(M13-L13<=3,"Stable","Sensitive") -> Stable
A14: =Scorecard!A15 -> Manufacturing | B14: =(IF(ISNUMBER(Scorecard!J15),Scorecard!J15,Inputs!$B$4)*Inputs!B$9+IF(ISNUMBER(Scorecard!K15),Scorecard!K15,Inputs!$B$4)*Inputs!C$9+IF(ISNUMBER(Scorecard!L15),Scorecard!L15,Inputs!$B$4)*Inputs!D$9+IF(ISNUMBER(Scorecard!M15),Scorecard!M15,Inputs!$B$4)*Inputs!E$9+IF(ISNUMBER(Scorecard!N15),Scorecard!N15,Inputs!$B$4)*Inputs!F$9)/Inputs!$G$9 -> 30.477508 | C14: =(IF(ISNUMBER(Scorecard!J15),Scorecard!J15,Inputs!$B$4)*Inputs!B$10+IF(ISNUMBER(Scorecard!K15),Scorecard!K15,Inputs!$B$4)*Inputs!C$10+IF(ISNUMBER(Scorecard!L15),Scorecard!L15,Inputs!$B$4)*Inputs!D$10+IF(ISNUMBER(Scorecard!M15),Scorecard!M15,Inputs!$B$4)*Inputs!E$10+IF(ISNUMBER(Scorecard!N15),Scorecard!N15,Inputs!$B$4)*Inputs!F$10)/Inputs!$G$10 -> 26.973511 | D14: =(IF(ISNUMBER(Scorecard!J15),Scorecard!J15,Inputs!$B$4)*Inputs!B$11+IF(ISNUMBER(Scorecard!K15),Scorecard!K15,Inputs!$B$4)*Inputs!C$11+IF(ISNUMBER(Scorecard!L15),Scorecard!L15,Inputs!$B$4)*Inputs!D$11+IF(ISNUMBER(Scorecard!M15),Scorecard!M15,Inputs!$B$4)*Inputs!E$11+IF(ISNUMBER(Scorecard!N15),Scorecard!N15,Inputs!$B$4)*Inputs!F$11)/Inputs!$G$11 -> 30.470157 | E14: =(IF(ISNUMBER(Scorecard!J15),Scorecard!J15,Inputs!$B$4)*Inputs!B$12+IF(ISNUMBER(Scorecard!K15),Scorecard!K15,Inputs!$B$4)*Inputs!C$12+IF(ISNUMBER(Scorecard!L15),Scorecard!L15,Inputs!$B$4)*Inputs!D$12+IF(ISNUMBER(Scorecard!M15),Scorecard!M15,Inputs!$B$4)*Inputs!E$12+IF(ISNUMBER(Scorecard!N15),Scorecard!N15,Inputs!$B$4)*Inputs!F$12)/Inputs!$G$12 -> 33.159628 | F14: =(IF(ISNUMBER(Scorecard!J15),Scorecard!J15,Inputs!$B$4)*Inputs!B$13+IF(ISNUMBER(Scorecard!K15),Scorecard!K15,Inputs!$B$4)*Inputs!C$13+IF(ISNUMBER(Scorecard!L15),Scorecard!L15,Inputs!$B$4)*Inputs!D$13+IF(ISNUMBER(Scorecard!M15),Scorecard!M15,Inputs!$B$4)*Inputs!E$13+IF(ISNUMBER(Scorecard!N15),Scorecard!N15,Inputs!$B$4)*Inputs!F$13)/Inputs!$G$13 -> 28.952254 | G14: =RANK(B14,B$5:B$14) -> 9 | H14: =RANK(C14,C$5:C$14) -> 9 | I14: =RANK(D14,D$5:D$14) -> 9 | J14: =RANK(E14,E$5:E$14) -> 6 | K14: =RANK(F14,F$5:F$14) -> 9 | L14: =MIN(G14:K14) -> 6 | M14: =MAX(G14:K14) -> 9 | N14: =IF(M14-L14<=3,"Stable","Sensitive") -> Stable

Sheet Inputs
A1: Inputs and scenario weights
A2: Weights are % of the total score. Pick the scenario used on the Scorecard.
A3: Selected scenario | B3: Balanced
A4: Neutral score for missing credit pillar | B4: 50
A5: Tier cut-off: Lead = rank at or below | B5: 3
A6: Tier cut-off: Grow = rank at or below | B6: 7
A8: Scenario | B8: Scale | C8: Recent growth | D8: Track record | E8: Credit demand | F8: Credit health | G8: Total
A9: Balanced | B9: 20 | C9: 25 | D9: 15 | E9: 20 | F9: 20 | G9: =SUM(B9:F9) -> 100
A10: Growth-led | B10: 10 | C10: 35 | D10: 25 | E10: 20 | F10: 10 | G10: =SUM(B10:F10) -> 100
A11: Risk-aware | B11: 20 | C11: 15 | D11: 10 | E11: 15 | F11: 40 | G11: =SUM(B11:F11) -> 100
A12: Scale-led | B12: 45 | C12: 15 | D12: 10 | E12: 15 | F12: 15 | G12: =SUM(B12:F12) -> 100
A13: Equal | B13: 20 | C13: 20 | D13: 20 | E13: 20 | F13: 20 | G13: =SUM(B13:F13) -> 100

Sheet GDP
A1: KNBS real GDP by activity (constant 2016 prices, KSh million)
A2: Source: KNBS Quarterly Gross Domestic Product Report, First Quarter 2026, Table 2. Column B is the editable group mapping.
A4: Activity | B4: Industry group | C4: FY2021 | D4: FY2024 | E4: FY2025 | F4: Q1 2025 | G4: Q1 2026 | H4: Growth 2025 % | I4: Growth Q1 2026 %
A5: Agriculture | B5: Agribusiness | C5: 1699959 | D5: 1862520 | E5: 1920338 | F5: 541319 | G5: 568027 | H5: =E5/D5*100-100 -> 3.1042888 | I5: =G5/F5*100-100 -> 4.9338745
A6: Mining & Quarrying | B6: Energy & Resources | C6: 103842 | D6: 97768 | E6: 112338 | F6: 25628 | G6: 27954 | H6: =E6/D6*100-100 -> 14.902627 | I6: =G6/F6*100-100 -> 9.0760106
A7: Manufacturing | B7: Manufacturing | C7: 810827 | D7: 874876 | E7: 892166 | F7: 221136 | G7: 230901 | H7: =E7/D7*100-100 -> 1.9762801 | I7: =G7/F7*100-100 -> 4.4158346
A8: Electricity & Water Supply | B8: Energy & Resources | C8: 231759 | D8: 259182 | E8: 272702 | F8: 65715 | G8: 68571 | H8: =E8/D8*100-100 -> 5.2164116 | I8: =G8/F8*100-100 -> 4.3460397
A9: Construction | B9: Real Estate & Construction | C9: 552764 | D9: 588156 | E9: 628320 | F9: 150281 | G9: 160133 | H9: =E9/D9*100-100 -> 6.8288005 | I9: =G9/F9*100-100 -> 6.555719
A10: Wholesale & Retail Trade | B10: Consumer & Retail | C10: 786202 | D10: 874817 | E10: 905941 | F10: 239942 | G10: 249638 | H10: =E10/D10*100-100 -> 3.5577727 | I10: =G10/F10*100-100 -> 4.0409766
A11: Accommodation & Food Services | B11: Consumer & Retail | C11: 81037 | D11: 172785 | E11: 199664 | F11: 47352 | G11: 54331 | H11: =E11/D11*100-100 -> 15.556327 | I11: =G11/F11*100-100 -> 14.738554
A12: Transportation & Storage | B12: Transport & Logistics | C12: 891983 | D12: 1038796 | E12: 1077187 | F12: 255011 | G12: 264187 | H12: =E12/D12*100-100 -> 3.6957208 | I12: =G12/F12*100-100 -> 3.5982762
A13: Information & Communication | B13: Technology, Media & Telecom | C13: 290224 | D13: 373860 | E13: 391886 | F13: 96655 | G13: 101463 | H13: =E13/D13*100-100 -> 4.821591 | I13: =G13/F13*100-100 -> 4.9743935
A14: Financial & Insurance | B14: Financial Services | C14: 802964 | D14: 1065163 | E14: 1134626 | F14: 257934 | G14: 274128 | H14: =E14/D14*100-100 -> 6.5213493 | I14: =G14/F14*100-100 -> 6.2783503
A15: Public Administration | B15: Public Sector & Development | C15: 564957 | D15: 677991 | E15: 734372 | F15: 174665 | G15: 184616 | H15: =E15/D15*100-100 -> 8.3158921 | I15: =G15/F15*100-100 -> 5.6971918
A16: Professional, Admin & Support Services | B16: Excluded | C16: 244148 | D16: 312376 | E16: 328078 | F16: 79636 | G16: 81559 | H16: =E16/D16*100-100 -> 5.0266346 | I16: =G16/F16*100-100 -> 2.4147371
... A21: FISIM | B21: Excluded | C21: -287975 | D21: -325317 | E21: -325971 | F21: -80173 | G21: -76917 | H21: =E21/D21*100-100 -> 0.20103468 | I21: =G21/F21*100-100 -> -4.0612176
A22: All industries at basic prices (published) | C22: 8597270 | D22: 9993801 | E22: 10470414 | F22: 2613759 | G22: 2753654
A23: Sum of activities listed (excludes FISIM adjustment) | C23: =SUM(C5:C21) -> 8597271 | D23: =SUM(D5:D21) -> 9993801 | E23: =SUM(E5:E21) -> 10470413 | F23: =SUM(F5:F21) -> 2613758 | G23: =SUM(G5:G21) -> 2753654
A24: Difference vs published (FISIM) | C24: =C22-C23 -> -1 | D24: =D22-D23 -> 0 | E24: =E22-E23 -> 1 | F24: =F22-F23 -> 1 | G24: =G22-G23 -> 0

Sheet Credit_Raw
A1: CBK bank lending, NPLs and credit officer survey by sector
A2: Sources: CBK Bank Supervision Annual Report 2025, Table 18 (Dec 2025); CBK Credit Officer Survey, quarter ended June 2026 (% of respondents).
A4: Bank sector | B4: Loan accounts | C4: Gross loans KSh m | D4: Gross NPLs KSh m | E4: NPL ratio % | F4: Demand: increased % | G4: Demand: unchanged % | H4: Demand: decreased % | I4: Standards: tightened % | J4: Standards: eased % | K4: NPL outlook: increase % | L4: NPL outlook: decrease %
A5: Trade | B5: 610882 | C5: 857832.3 | D5: 170564.2 | E5: =D5/C5*100 -> 19.883164 | F5: 65 | G5: 30 | H5: 5 | I5: 16 | J5: 29 | K5: 29 | L5: 39
A6: Real Estate | B6: 30459 | C6: 511116.3 | D6: 113797.5 | E6: =D6/C6*100 -> 22.264502 | F6: 28 | G6: 44 | H6: 28 | I6: 30 | J6: 8 | K6: 27 | L6: 27
A7: Manufacturing | B7: 34456 | C7: 584989.3 | D7: 107629.6 | E7: =D7/C7*100 -> 18.398559 | F7: 41 | G7: 49 | H7: 11 | I7: 13 | J7: 21 | K7: 21 | L7: 34
A8: Personal and Household | B8: 14849679 | C8: 1176958.3 | D8: 114045.7 | E8: =D8/C8*100 -> 9.6898675 | F8: 66 | G8: 29 | H8: 6 | I8: 27 | J8: 24 | K8: 35 | L8: 43
A9: Building and Construction | B9: 17904 | C9: 175519.6 | D9: 51767.8 | E9: =D9/C9*100 -> 29.494028 | F9: 42 | G9: 53 | H9: 6 | I9: 16 | J9: 11 | K9: 24 | L9: 41
A10: Transport and Communication | B10: 53357 | C10: 321105.5 | D10: 53180.9 | E10: =D10/C10*100 -> 16.561815 | F10: 32 | G10: 43 | H10: 24 | I10: 18 | J10: 11 | K10: 18 | L10: 37
A11: Agriculture | B11: 127031 | C11: 197895.5 | D11: 38134.6 | E11: =D11/C11*100 -> 19.270069 | F11: 35 | G11: 49 | H11: 16 | I11: 13 | J11: 18 | K11: 16 | L11: 29
A12: Tourism, Restaurant and Hotels | B12: 10902 | C12: 99113.8 | D12: 22657.2 | E12: =D12/C12*100 -> 22.859783 | F12: 19 | G12: 56 | H12: 25 | I12: 19 | J12: 8 | K12: 24 | L12: 35
A13: Energy and Water | B13: 5028 | C13: 142807.6 | D13: 9777.9 | E13: =D13/C13*100 -> 6.8469045 | F13: 38 | G13: 54 | H13: 8 | I13: 11 | J13: 11 | K13: 19 | L13: 22
A14: Financial Services | B14: 18277 | C14: 241698.4 | D14: 7864.2 | E14: =D14/C14*100 -> 3.2537245 | F14: 38 | G14: 46 | H14: 16 | I14: 11 | J14: 11 | K14: 13 | L14: 34
A15: Mining and Quarrying | B15: 1133 | C15: 38127.5 | D15: 7511.5 | E15: =D15/C15*100 -> 19.701003 | F15: 14 | G15: 84 | H15: 3 | I15: 13 | J15: 5 | K15: 11 | L15: 26
A16: Total | B16: =SUM(B5:B15) -> 15759108 | C16: =SUM(C5:C15) -> 4347164.1 | D16: =SUM(D5:D15) -> 696931.1 | E16: =D16/C16*100 -> 16.031856

Sheet Credit_Map
A1: Mapping of industry groups to CBK bank sectors
A2: Editable (blue). Transport and Communication is shared by two groups.
A4: Industry group | B4: Bank sector | C4: Gross loans | D4: Gross NPLs | E4: Demand up % | F4: Demand down %
A5: Financial Services | B5: Financial Services | C5: =INDEX(Credit_Raw!$C$5:$C$15,MATCH($B5,Credit_Raw!$A$5:$A$15,0)) -> 241698.4 | D5: =INDEX(Credit_Raw!$D$5:$D$15,MATCH($B5,Credit_Raw!$A$5:$A$15,0)) -> 7864.2 | E5: =INDEX(Credit_Raw!$F$5:$F$15,MATCH($B5,Credit_Raw!$A$5:$A$15,0)) -> 38 | F5: =INDEX(Credit_Raw!$H$5:$H$15,MATCH($B5,Credit_Raw!$A$5:$A$15,0)) -> 16
A6: Energy & Resources | B6: Energy and Water | C6: =INDEX(Credit_Raw!$C$5:$C$15,MATCH($B6,Credit_Raw!$A$5:$A$15,0)) -> 142807.6 | D6: =INDEX(Credit_Raw!$D$5:$D$15,MATCH($B6,Credit_Raw!$A$5:$A$15,0)) -> 9777.9 | E6: =INDEX(Credit_Raw!$F$5:$F$15,MATCH($B6,Credit_Raw!$A$5:$A$15,0)) -> 38 | F6: =INDEX(Credit_Raw!$H$5:$H$15,MATCH($B6,Credit_Raw!$A$5:$A$15,0)) -> 8
A7: Energy & Resources | B7: Mining and Quarrying | C7: =INDEX(Credit_Raw!$C$5:$C$15,MATCH($B7,Credit_Raw!$A$5:$A$15,0)) -> 38127.5 | D7: =INDEX(Credit_Raw!$D$5:$D$15,MATCH($B7,Credit_Raw!$A$5:$A$15,0)) -> 7511.5 | E7: =INDEX(Credit_Raw!$F$5:$F$15,MATCH($B7,Credit_Raw!$A$5:$A$15,0)) -> 14 | F7: =INDEX(Credit_Raw!$H$5:$H$15,MATCH($B7,Credit_Raw!$A$5:$A$15,0)) -> 3
A8: Technology, Media & Telecom | B8: Transport and Communication | C8: =INDEX(Credit_Raw!$C$5:$C$15,MATCH($B8,Credit_Raw!$A$5:$A$15,0)) -> 321105.5 | D8: =INDEX(Credit_Raw!$D$5:$D$15,MATCH($B8,Credit_Raw!$A$5:$A$15,0)) -> 53180.9 | E8: =INDEX(Credit_Raw!$F$5:$F$15,MATCH($B8,Credit_Raw!$A$5:$A$15,0)) -> 32 | F8: =INDEX(Credit_Raw!$H$5:$H$15,MATCH($B8,Credit_Raw!$A$5:$A$15,0)) -> 24
A9: Transport & Logistics | B9: Transport and Communication | C9: =INDEX(Credit_Raw!$C$5:$C$15,MATCH($B9,Credit_Raw!$A$5:$A$15,0)) -> 321105.5 | D9: =INDEX(Credit_Raw!$D$5:$D$15,MATCH($B9,Credit_Raw!$A$5:$A$15,0)) -> 53180.9 | E9: =INDEX(Credit_Raw!$F$5:$F$15,MATCH($B9,Credit_Raw!$A$5:$A$15,0)) -> 32 | F9: =INDEX(Credit_Raw!$H$5:$H$15,MATCH($B9,Credit_Raw!$A$5:$A$15,0)) -> 24
A10: Consumer & Retail | B10: Trade | C10: =INDEX(Credit_Raw!$C$5:$C$15,MATCH($B10,Credit_Raw!$A$5:$A$15,0)) -> 857832.3 | D10: =INDEX(Credit_Raw!$D$5:$D$15,MATCH($B10,Credit_Raw!$A$5:$A$15,0)) -> 170564.2 | E10: =INDEX(Credit_Raw!$F$5:$F$15,MATCH($B10,Credit_Raw!$A$5:$A$15,0)) -> 65 | F10: =INDEX(Credit_Raw!$H$5:$H$15,MATCH($B10,Credit_Raw!$A$5:$A$15,0)) -> 5
A11: Consumer & Retail | B11: Tourism, Restaurant and Hotels | C11: =INDEX(Credit_Raw!$C$5:$C$15,MATCH($B11,Credit_Raw!$A$5:$A$15,0)) -> 99113.8 | D11: =INDEX(Credit_Raw!$D$5:$D$15,MATCH($B11,Credit_Raw!$A$5:$A$15,0)) -> 22657.2 | E11: =INDEX(Credit_Raw!$F$5:$F$15,MATCH($B11,Credit_Raw!$A$5:$A$15,0)) -> 19 | F11: =INDEX(Credit_Raw!$H$5:$H$15,MATCH($B11,Credit_Raw!$A$5:$A$15,0)) -> 25
A12: Agribusiness | B12: Agriculture | C12: =INDEX(Credit_Raw!$C$5:$C$15,MATCH($B12,Credit_Raw!$A$5:$A$15,0)) -> 197895.5 | D12: =INDEX(Credit_Raw!$D$5:$D$15,MATCH($B12,Credit_Raw!$A$5:$A$15,0)) -> 38134.6 | E12: =INDEX(Credit_Raw!$F$5:$F$15,MATCH($B12,Credit_Raw!$A$5:$A$15,0)) -> 35 | F12: =INDEX(Credit_Raw!$H$5:$H$15,MATCH($B12,Credit_Raw!$A$5:$A$15,0)) -> 16
A13: Real Estate & Construction | B13: Real Estate | C13: =INDEX(Credit_Raw!$C$5:$C$15,MATCH($B13,Credit_Raw!$A$5:$A$15,0)) -> 511116.3 | D13: =INDEX(Credit_Raw!$D$5:$D$15,MATCH($B13,Credit_Raw!$A$5:$A$15,0)) -> 113797.5 | E13: =INDEX(Credit_Raw!$F$5:$F$15,MATCH($B13,Credit_Raw!$A$5:$A$15,0)) -> 28 | F13: =INDEX(Credit_Raw!$H$5:$H$15,MATCH($B13,Credit_Raw!$A$5:$A$15,0)) -> 28
A14: Real Estate & Construction | B14: Building and Construction | C14: =INDEX(Credit_Raw!$C$5:$C$15,MATCH($B14,Credit_Raw!$A$5:$A$15,0)) -> 175519.6 | D14: =INDEX(Credit_Raw!$D$5:$D$15,MATCH($B14,Credit_Raw!$A$5:$A$15,0)) -> 51767.8 | E14: =INDEX(Credit_Raw!$F$5:$F$15,MATCH($B14,Credit_Raw!$A$5:$A$15,0)) -> 42 | F14: =INDEX(Credit_Raw!$H$5:$H$15,MATCH($B14,Credit_Raw!$A$5:$A$15,0)) -> 6
A15: Manufacturing | B15: Manufacturing | C15: =INDEX(Credit_Raw!$C$5:$C$15,MATCH($B15,Credit_Raw!$A$5:$A$15,0)) -> 584989.3 | D15: =INDEX(Credit_Raw!$D$5:$D$15,MATCH($B15,Credit_Raw!$A$5:$A$15,0)) -> 107629.6 | E15: =INDEX(Credit_Raw!$F$5:$F$15,MATCH($B15,Credit_Raw!$A$5:$A$15,0)) -> 41 | F15: =INDEX(Credit_Raw!$H$5:$H$15,MATCH($B15,Credit_Raw!$A$5:$A$15,0)) -> 11

Sheet Signals
A1: Real-economy signals, 2021-2025
A2: Source: KNBS Economic Survey 2026, Annex 1 Table 0 (2025 provisional).
A4: Indicator | B4: Unit | C4: 2021 | D4: 2022 | E4: 2023 | F4: 2024 | G4: 2025 | H4: Growth 2025 % | I4: CAGR 2021-25 %
A5: GDP (Current) at Market Prices | B5: KSh Mn | C5: 12027662 | D5: 13489642 | E5: 15033610 | F5: 16232295 | G5: 17577557 | H5: =G5/F5*100-100 -> 8.2875676 | I5: =((G5/C5)^(1/4)-1)*100 -> 9.9497714
A6: Money Supply (M3) | B6: KSh Mn | C6: 4689439 | D6: 5042419 | E6: 6044533 | F6: 6048537 | G6: 6731191 | H6: =G6/F6*100-100 -> 11.286266 | I6: =((G6/C6)^(1/4)-1)*100 -> 9.4568021
A7: Total domestic credit | B7: KSh Mn | C7: 5566513 | D7: 6246348 | E7: 7041087 | F7: 7140299 | G7: 7862296 | H7: =G7/F7*100-100 -> 10.111579 | I7: =((G7/C7)^(1/4)-1)*100 -> 9.0163257
A8: Tea-marketed production | B8: '000 tonnes | C8: 537.8 | D8: 535 | E8: 570.3 | F8: 598.5 | G8: 550.4 | H8: =G8/F8*100-100 -> -8.0367586 | I8: =((G8/C8)^(1/4)-1)*100 -> 0.5806428
A9: Fresh Horticultural Produce exports | B9: '000 tonnes | C9: 405.5 | D9: 391.5 | E9: 468.4 | F9: 402.2 | G9: 457.9 | H9: =G9/F9*100-100 -> 13.848831 | I9: =((G9/C9)^(1/4)-1)*100 -> 3.0848744
A10: Milk sold centrally | B10: Mn litres | C10: 801.9 | D10: 755.3 | E10: 810.8 | F10: 909 | G10: 1013.7 | H10: =G10/F10*100-100 -> 11.518152 | I10: =((G10/C10)^(1/4)-1)*100 -> 6.0345282
A11: Manufacturing output | B11: KSh Mn | C11: 2700161.2 | D11: 3168615 | E11: 3511497.7 | F11: 3689334.1 | G11: 3817390.6 | H11: =G11/F11*100-100 -> 3.4709922 | I11: =((G11/C11)^(1/4)-1)*100 -> 9.042105
A12: Construction output | B12: KSh Mn | C12: 1821644 | D12: 2042781.5 | E12: 2119786.8 | F12: 2171266 | G12: 2374337.8 | H12: =G12/F12*100-100 -> 9.352691 | I12: =((G12/C12)^(1/4)-1)*100 -> 6.8488248
A13: Cement Consumption | B13: '000 tonnes | C13: 9098.4 | D13: 9456.8 | E13: 9195.8 | F13: 8542.7 | G13: 10280.2 | H13: =G13/F13*100-100 -> 20.339003 | I13: =((G13/C13)^(1/4)-1)*100 -> 3.1001114
A14: Electricity consumption | B14: GWh | C14: 9565.4 | D14: 10008.4 | E14: 10320.6 | F14: 10751.7 | G14: 11785.5 | H14: =G14/F14*100-100 -> 9.6152236 | I14: =((G14/C14)^(1/4)-1)*100 -> 5.356472
A15: Rail freight | B15: '000 tonnes | C15: 6051 | D15: 6877 | E15: 7534 | F15: 7560 | G15: 8415 | H15: =G15/F15*100-100 -> 11.309524 | I15: =((G15/C15)^(1/4)-1)*100 -> 8.5942279
A16: Air passengers handled | B16: '000 No. | C16: 6703.5 | D16: 10238.6 | E16: 12205.8 | F16: 12831.8 | G16: 12676.6 | H16: =G16/F16*100-100 -> -1.2094952 | I16: =((G16/C16)^(1/4)-1)*100 -> 17.266859
... A23: Total National Government Expenditure | B23: KSh Mn | C23: 3027518 | D23: 3218186.9 | E23: 3605209.1 | F23: 4077992.4 | G23: 4269579.8 | H23: =G23/F23*100-100 -> 4.6980813 | I23: =((G23/C23)^(1/4)-1)*100 -> 8.9744285

Sheet Python_Ref
A1: Independent Python results (analysis/model.py)
A3: group | B3: value_added_2025_ksh_m | C3: share_of_gdp_pct | D3: growth_2025_pct | E3: cagr_2021_25_pct | F3: growth_q1_2026_pct | G3: gross_loans_ksh_m | H3: npl_ratio_pct | I3: credit_demand_net_pct | J3: score_Balanced | K3: score_Growth-led | L3: score_Risk-aware | M3: score_Scale-led | N3: score_Equal | O3: rank_Balanced | P3: rank_Growth-led | Q3: rank_Risk-aware | R3: rank_Scale-led | S3: rank_Equal
A4: Financial Services | B4: 1134626 | C4: 10.836496 | D4: 6.5213493 | E4: 9.0282808 | F4: 6.2783503 | G4: 241698.4 | H4: 3.2537245 | I4: 22 | J4: 76.746877 | K4: 81.47324 | L4: 80.196976 | M4: 68.381069 | N4: 76.746877 | O4: 1 | P4: 1 | Q4: 1 | R4: 1 | S4: 1
A5: Energy & Resources | B5: 385040 | C5: 3.6774095 | D5: 7.8694495 | E5: 3.4953054 | F5: 5.6731222 | G5: 180935.1 | H5: 9.555581 | I5: 25.99623 | J5: 45.253634 | K5: 46.880818 | L5: 48.662768 | M5: 33.127225 | N5: 42.197172 | O5: 4 | P5: 4 | Q5: 4 | R5: 7 | S5: 4
A6: Technology, Media & Telecom | B6: 391886 | C6: 3.7427937 | D6: 4.821591 | E6: 7.7969831 | F6: 4.9743935 | G6: 321105.5 | H6: 16.561815 | I6: 8 | J6: 33.893572 | K6: 42.739605 | L6: 31.930236 | M6: 24.89486 | N6: 35.394807 | O6: 7 | P6: 5 | Q6: 8 | R6: 9 | S6: 7
A7: Transport & Logistics | B7: 1077187 | C7: 10.287912 | D7: 3.6957208 | E7: 4.8295283 | F7: 3.5982762 | G7: 321105.5 | H7: 16.561815 | I7: 8 | J7: 22.56725 | K7: 17.666664 | L7: 27.98336 | M7: 31.253863 | N7: 24.390975 | O7: 10 | P7: 10 | Q7: 10 | R7: 8 | S7: 10
A8: Public Sector & Development | B8: 1273606 | C8: 12.163855 | D8: 5.9295658 | E8: 5.5228987 | F8: 5.9081245 | J8: 60.810548 | K8: 63.015984 | L8: 57.343703 | M8: 60.117842 | N8: 58.849495 | O8: 3 | P8: 3 | Q8: 2 | R8: 3 | S8: 3
A9: Health | B9: 257935 | C9: 2.4634652 | D9: 5.5250992 | E9: 4.8367026 | F9: 4.3111255 | J9: 32.136989 | K9: 33.455106 | L9: 35.148024 | M9: 22.648024 | N9: 32.636235 | O9: 8 | P9: 8 | Q9: 6 | R9: 10 | S9: 8
A10: Consumer & Retail | B10: 1105605 | C10: 10.559325 | D10: 5.5367401 | E10: 6.2588958 | F10: 5.8041588 | G10: 956946.1 | H10: 20.191461 | I10: 53.164181 | J10: 63.249496 | K10: 70.311323 | L10: 50.873435 | M10: 58.921558 | N10: 62.039172 | O10: 2 | P10: 2 | Q10: 3 | R10: 4 | S10: 2
